2024-11-04 20:52:07,323 - INFO - Stop polling...
2024-11-04 20:52:07,325 - WARNING - Goodbye!
2024-11-04 20:52:12,028 - INFO - Bot: RabbitHole Bot [@rabbit4ogs_bot]
2024-11-04 20:52:12,437 - WARNING - Updates were skipped successfully.
2024-11-04 20:52:12,437 - INFO - Start polling.
2024-11-04 20:52:55,389 - INFO - Stop polling...
2024-11-04 20:52:55,390 - WARNING - Goodbye!
2024-11-04 20:53:02,567 - INFO - Bot: RabbitHole Bot [@rabbit4ogs_bot]
2024-11-04 20:53:03,048 - WARNING - Updates were skipped successfully.
2024-11-04 20:53:03,052 - INFO - Start polling.
2024-11-04 20:55:07,282 - INFO - Stop polling...
2024-11-04 20:55:07,294 - WARNING - Goodbye!
2024-11-04 20:55:13,535 - INFO - Bot: RabbitHole Bot [@rabbit4ogs_bot]
2024-11-04 20:55:13,970 - WARNING - Updates were skipped successfully.
2024-11-04 20:55:13,971 - INFO - Start polling.
2024-11-04 20:56:56,970 - INFO - Stop polling...
2024-11-04 20:56:56,971 - WARNING - Goodbye!
2024-11-04 20:57:01,821 - INFO - Bot: RabbitHole Bot [@rabbit4ogs_bot]
2024-11-04 20:57:02,478 - WARNING - Updates were skipped successfully.
2024-11-04 20:57:02,487 - INFO - Start polling.
2024-11-04 20:57:18,576 - INFO - Sent message ID: 22, Chat ID: -1002487692776, Date: 2024-11-04 20:57:19, Text: channel post 7
2024-11-04 20:57:19,699 - INFO - Sent message ID: 24, Chat ID: -1002392924508, Date: 2024-11-04 20:57:20, Text: channel post 7
2024-11-04 20:58:38,165 - ERROR - Invalid message ID for deletion: -OAscoEbnjLRENOf0dYz. Error: invalid literal for int() with base 10: '-OAscoEbnjLRENOf0dYz'
2024-11-04 20:58:38,174 - ERROR - Invalid message ID for deletion: -OAscoQWDq_rVXfpQs9Y. Error: invalid literal for int() with base 10: '-OAscoQWDq_rVXfpQs9Y'
2024-11-04 20:58:38,556 - INFO - Deleted message ID: -OAsco-TKCALG4GyOHgX from database.
2024-11-04 20:58:38,556 - ERROR - Invalid message ID for deletion: -OAsdIZhWZe_bWHaiK1U. Error: invalid literal for int() with base 10: '-OAsdIZhWZe_bWHaiK1U'
2024-11-04 20:58:38,556 - ERROR - Invalid message ID for deletion: -OAsdIsRZubulh9117g5. Error: invalid literal for int() with base 10: '-OAsdIsRZubulh9117g5'
2024-11-04 20:58:38,964 - INFO - Deleted message ID: -OAsdIK4mit78lToqM8T from database.
2024-11-04 20:58:38,965 - ERROR - Invalid message ID for deletion: -OAshFSINxJWo_1IdxyJ. Error: invalid literal for int() with base 10: '-OAshFSINxJWo_1IdxyJ'
2024-11-04 20:58:38,965 - ERROR - Invalid message ID for deletion: -OAshFgHtfnIrHmfWRxI. Error: invalid literal for int() with base 10: '-OAshFgHtfnIrHmfWRxI'
2024-11-04 20:58:39,375 - INFO - Deleted message ID: -OAshFAMTuT-5VnPaCaj from database.
2024-11-04 20:58:39,376 - ERROR - Invalid message ID for deletion: -OAsiCY8FExa5IB8AUxg. Error: invalid literal for int() with base 10: '-OAsiCY8FExa5IB8AUxg'
2024-11-04 20:58:39,376 - ERROR - Invalid message ID for deletion: -OAsiCovZajEjMdfdvbd. Error: invalid literal for int() with base 10: '-OAsiCovZajEjMdfdvbd'
2024-11-04 20:58:39,690 - INFO - Deleted message ID: -OAsiCFaCfjGfEILcAN_ from database.
2024-11-04 20:58:39,690 - ERROR - Invalid message ID for deletion: -OAsicAoAoVfjRFkDXgb. Error: invalid literal for int() with base 10: '-OAsicAoAoVfjRFkDXgb'
2024-11-04 20:58:39,691 - ERROR - Invalid message ID for deletion: -OAsicPZNfYqb_hHVsJE. Error: invalid literal for int() with base 10: '-OAsicPZNfYqb_hHVsJE'
2024-11-04 20:58:41,012 - INFO - Deleted message ID: -OAsibtPXNCE1je3tqOj from database.
2024-11-04 20:58:41,012 - ERROR - Invalid message ID for deletion: -OAsj4RMNVt7LYLfkqYn. Error: invalid literal for int() with base 10: '-OAsj4RMNVt7LYLfkqYn'
2024-11-04 20:58:41,013 - ERROR - Invalid message ID for deletion: -OAsj4fhCe8fcvyERB74. Error: invalid literal for int() with base 10: '-OAsj4fhCe8fcvyERB74'
2024-11-04 20:58:41,416 - INFO - Deleted message ID: -OAsj45h_L_vuMRkK1TW from database.
2024-11-04 20:58:41,416 - ERROR - Invalid message ID for deletion: -OAsjFgJy1xH-meebTxh. Error: invalid literal for int() with base 10: '-OAsjFgJy1xH-meebTxh'
2024-11-04 20:58:41,416 - ERROR - Invalid message ID for deletion: -OAsjG68wMTXfQDg03N1. Error: invalid literal for int() with base 10: '-OAsjG68wMTXfQDg03N1'
2024-11-04 20:58:41,727 - INFO - Deleted message ID: -OAsjFN8JF1NXElbpaIA from database.
2024-11-04 20:58:42,244 - INFO - Deleted message ID: -OAsjoQVv5cBmKvrGThO from database.
2024-11-04 20:58:42,244 - ERROR - Invalid message ID for deletion: -OAskCH7xN8IMDUtmFjT. Error: invalid literal for int() with base 10: '-OAskCH7xN8IMDUtmFjT'
2024-11-04 20:58:42,245 - ERROR - Invalid message ID for deletion: -OAskCYuZwx-YQExFz6n. Error: invalid literal for int() with base 10: '-OAskCYuZwx-YQExFz6n'
2024-11-04 20:58:42,665 - INFO - Deleted message ID: -OAskByfWWrm-6bl6A1T from database.
2024-11-04 20:59:25,290 - INFO - Stop polling...
2024-11-04 20:59:25,300 - WARNING - Goodbye!
2024-11-04 20:59:45,605 - INFO - Bot: RabbitHole Bot [@rabbit4ogs_bot]
2024-11-04 20:59:46,481 - WARNING - Updates were skipped successfully.
2024-11-04 20:59:46,482 - INFO - Start polling.
2024-11-04 21:00:16,183 - INFO - Sent message ID: 23, Chat ID: -1002487692776, Date: 2024-11-04 21:00:17, Text: new channel post
2024-11-04 21:00:18,098 - INFO - Sent message ID: 25, Chat ID: -1002392924508, Date: 2024-11-04 21:00:18, Text: new channel post
2024-11-04 21:01:36,134 - INFO - Stop polling...
2024-11-04 21:01:36,138 - WARNING - Goodbye!
2024-11-04 21:01:41,630 - INFO - Bot: RabbitHole Bot [@rabbit4ogs_bot]
2024-11-04 21:01:42,870 - WARNING - Updates were skipped successfully.
2024-11-04 21:01:42,870 - INFO - Start polling.
2024-11-04 21:01:52,299 - ERROR - Invalid message ID for deletion: -OAsksdv4NwLsjfD1BdT. Error: invalid literal for int() with base 10: '-OAsksdv4NwLsjfD1BdT'
2024-11-04 21:01:52,300 - ERROR - Invalid message ID for deletion: -OAskt6kTWyUyFQxY6Dt. Error: invalid literal for int() with base 10: '-OAskt6kTWyUyFQxY6Dt'
2024-11-04 21:01:52,695 - INFO - Deleted message ID: -OAsksNz5O5OIChu7rvz from database.
2024-11-04 21:03:33,712 - INFO - Stop polling...
2024-11-04 21:03:33,713 - WARNING - Goodbye!
2024-11-04 21:03:39,032 - INFO - Bot: RabbitHole Bot [@rabbit4ogs_bot]
2024-11-04 21:03:39,544 - WARNING - Updates were skipped successfully.
2024-11-04 21:03:39,545 - INFO - Start polling.
2024-11-04 21:04:30,384 - INFO - Sent message ID: 24, Chat ID: -1002487692776, Date: 2024-11-04 21:04:31, Text: new channel post2
2024-11-04 21:04:31,098 - INFO - Sent message ID: 26, Chat ID: -1002392924508, Date: 2024-11-04 21:04:32, Text: new channel post2
2024-11-04 21:05:44,511 - INFO - Stop polling...
2024-11-04 21:05:44,520 - WARNING - Goodbye!
2024-11-04 21:05:48,446 - INFO - Bot: RabbitHole Bot [@rabbit4ogs_bot]
2024-11-04 21:05:48,902 - WARNING - Updates were skipped successfully.
2024-11-04 21:05:48,902 - INFO - Start polling.
2024-11-04 21:09:21,864 - INFO - Stop polling...
2024-11-04 21:09:21,879 - WARNING - Goodbye!
2024-11-04 21:09:26,234 - INFO - Bot: RabbitHole Bot [@rabbit4ogs_bot]
2024-11-04 21:09:26,758 - WARNING - Updates were skipped successfully.
2024-11-04 21:09:26,759 - INFO - Start polling.
2024-11-04 21:09:42,415 - INFO - Sent message ID: 25 (Type: <class 'int'>)
2024-11-04 21:09:43,068 - INFO - Sent message ID: 27 (Type: <class 'int'>)
2024-11-04 21:11:36,607 - INFO - Stop polling...
2024-11-04 21:11:36,617 - WARNING - Goodbye!
2024-11-04 21:11:42,750 - INFO - Bot: RabbitHole Bot [@rabbit4ogs_bot]
2024-11-04 21:11:43,120 - WARNING - Updates were skipped successfully.
2024-11-04 21:11:43,120 - INFO - Start polling.
2024-11-04 21:11:58,365 - INFO - Sent message ID: 26 (Type: <class 'int'>)
2024-11-04 21:11:59,517 - INFO - Sent message ID: 28 (Type: <class 'int'>)
2024-11-04 21:17:01,628 - INFO - Stop polling...
2024-11-04 21:17:01,631 - WARNING - Goodbye!
2024-11-04 21:17:07,607 - INFO - Bot: RabbitHole Bot [@rabbit4ogs_bot]
2024-11-04 21:17:07,975 - WARNING - Updates were skipped successfully.
2024-11-04 21:17:07,977 - INFO - Start polling.
2024-11-04 21:17:14,330 - ERROR - Task exception was never retrieved
future: <Task finished name='Task-9' coro=<Dispatcher._process_polling_updates() done, defined at /Users/Scoring/Desktop/rabbit-bot/venv/lib/python3.11/site-packages/aiogram/dispatcher/dispatcher.py:407> exception=TypeError("delete_message() missing 1 required positional argument: 'admins'")>
Traceback (most recent call last):
  File "/Users/Scoring/Desktop/rabbit-bot/venv/lib/python3.11/site-packages/aiogram/dispatcher/dispatcher.py", line 415, in _process_polling_updates
    for responses in itertools.chain.from_iterable(await self.process_updates(updates, fast)):
                                                   ^^^^^^^^^^^^^^^^^^^^^^^^^^^^^^^^^^^^^^^^^
  File "/Users/Scoring/Desktop/rabbit-bot/venv/lib/python3.11/site-packages/aiogram/dispatcher/dispatcher.py", line 235, in process_updates
    return await asyncio.gather(*tasks)
           ^^^^^^^^^^^^^^^^^^^^^^^^^^^^
  File "/Users/Scoring/Desktop/rabbit-bot/venv/lib/python3.11/site-packages/aiogram/dispatcher/handler.py", line 117, in notify
    response = await handler_obj.handler(*args, **partial_data)
               ^^^^^^^^^^^^^^^^^^^^^^^^^^^^^^^^^^^^^^^^^^^^^^^^
  File "/Users/Scoring/Desktop/rabbit-bot/venv/lib/python3.11/site-packages/aiogram/dispatcher/dispatcher.py", line 256, in process_update
    return await self.message_handlers.notify(update.message)
           ^^^^^^^^^^^^^^^^^^^^^^^^^^^^^^^^^^^^^^^^^^^^^^^^^^
  File "/Users/Scoring/Desktop/rabbit-bot/venv/lib/python3.11/site-packages/aiogram/dispatcher/handler.py", line 117, in notify
    response = await handler_obj.handler(*args, **partial_data)
                     ^^^^^^^^^^^^^^^^^^^^^^^^^^^^^^^^^^^^^^^^^^
  File "/Users/Scoring/Desktop/rabbit-bot/newbot.py", line 73, in <lambda>
    lambda message: delete_message(message, ADMINS), commands=['deleteall']
                    ^^^^^^^^^^^^^^^^^^^^^^^^^^^^^^^
TypeError: delete_message() missing 1 required positional argument: 'admins'
2024-11-04 21:18:52,184 - INFO - Stop polling...
2024-11-04 21:18:52,194 - WARNING - Goodbye!
2024-11-04 21:21:51,842 - INFO - Bot: RabbitHole Bot [@rabbit4ogs_bot]
2024-11-04 21:21:52,289 - WARNING - Updates were skipped successfully.
2024-11-04 21:21:52,290 - INFO - Start polling.
2024-11-04 21:23:26,798 - ERROR - Task exception was never retrieved
future: <Task finished name='Task-13' coro=<Dispatcher._process_polling_updates() done, defined at /Users/Scoring/Desktop/rabbit-bot/venv/lib/python3.11/site-packages/aiogram/dispatcher/dispatcher.py:407> exception=TypeError('handle_delete_message() takes 1 positional argument but 2 were given')>
Traceback (most recent call last):
  File "/Users/Scoring/Desktop/rabbit-bot/venv/lib/python3.11/site-packages/aiogram/dispatcher/dispatcher.py", line 415, in _process_polling_updates
    for responses in itertools.chain.from_iterable(await self.process_updates(updates, fast)):
                                                   ^^^^^^^^^^^^^^^^^^^^^^^^^^^^^^^^^^^^^^^^^
  File "/Users/Scoring/Desktop/rabbit-bot/venv/lib/python3.11/site-packages/aiogram/dispatcher/dispatcher.py", line 235, in process_updates
    return await asyncio.gather(*tasks)
           ^^^^^^^^^^^^^^^^^^^^^^^^^^^^
  File "/Users/Scoring/Desktop/rabbit-bot/venv/lib/python3.11/site-packages/aiogram/dispatcher/handler.py", line 117, in notify
    response = await handler_obj.handler(*args, **partial_data)
               ^^^^^^^^^^^^^^^^^^^^^^^^^^^^^^^^^^^^^^^^^^^^^^^^
  File "/Users/Scoring/Desktop/rabbit-bot/venv/lib/python3.11/site-packages/aiogram/dispatcher/dispatcher.py", line 256, in process_update
    return await self.message_handlers.notify(update.message)
           ^^^^^^^^^^^^^^^^^^^^^^^^^^^^^^^^^^^^^^^^^^^^^^^^^^
  File "/Users/Scoring/Desktop/rabbit-bot/venv/lib/python3.11/site-packages/aiogram/dispatcher/handler.py", line 117, in notify
    response = await handler_obj.handler(*args, **partial_data)
                     ^^^^^^^^^^^^^^^^^^^^^^^^^^^^^^^^^^^^^^^^^^
  File "/Users/Scoring/Desktop/rabbit-bot/newbot.py", line 78, in <lambda>
    lambda message: handle_delete_message(message, ADMINS), commands=['deletemsg']
                    ^^^^^^^^^^^^^^^^^^^^^^^^^^^^^^^^^^^^^^
TypeError: handle_delete_message() takes 1 positional argument but 2 were given
2024-11-04 21:24:00,434 - INFO - Stop polling...
2024-11-04 21:24:00,445 - WARNING - Goodbye!
2024-11-04 21:24:05,739 - INFO - Bot: RabbitHole Bot [@rabbit4ogs_bot]
2024-11-04 21:24:06,344 - WARNING - Updates were skipped successfully.
2024-11-04 21:24:06,345 - INFO - Start polling.
2024-11-04 21:29:09,769 - INFO - Stop polling...
2024-11-04 21:29:09,773 - WARNING - Goodbye!
2024-11-04 21:29:13,715 - INFO - Bot: RabbitHole Bot [@rabbit4ogs_bot]
2024-11-04 21:29:14,085 - WARNING - Updates were skipped successfully.
2024-11-04 21:29:14,085 - INFO - Start polling.
2024-11-04 21:30:27,637 - INFO - Stop polling...
2024-11-04 21:30:27,876 - ERROR - Task exception was never retrieved
future: <Task finished name='Task-9' coro=<Dispatcher._process_polling_updates() done, defined at /Users/Scoring/Desktop/rabbit-bot/venv/lib/python3.11/site-packages/aiogram/dispatcher/dispatcher.py:407> exception=KeyboardInterrupt()>
Traceback (most recent call last):
  File "/Users/Scoring/Desktop/rabbit-bot/venv/lib/python3.11/site-packages/urllib3/connection.py", line 199, in _new_conn
    sock = connection.create_connection(
           ^^^^^^^^^^^^^^^^^^^^^^^^^^^^^
  File "/Users/Scoring/Desktop/rabbit-bot/venv/lib/python3.11/site-packages/urllib3/util/connection.py", line 60, in create_connection
    for res in socket.getaddrinfo(host, port, family, socket.SOCK_STREAM):
               ^^^^^^^^^^^^^^^^^^^^^^^^^^^^^^^^^^^^^^^^^^^^^^^^^^^^^^^^^^
  File "/Library/Frameworks/Python.framework/Versions/3.11/lib/python3.11/socket.py", line 962, in getaddrinfo
    for res in _socket.getaddrinfo(host, port, family, type, proto, flags):
               ^^^^^^^^^^^^^^^^^^^^^^^^^^^^^^^^^^^^^^^^^^^^^^^^^^^^^^^^^^^
socket.gaierror: [Errno 8] nodename nor servname provided, or not known

During handling of the above exception, another exception occurred:

Traceback (most recent call last):
  File "/Users/Scoring/Desktop/rabbit-bot/newbot.py", line 129, in <module>
    executor.start_polling(dp, skip_updates=True)
  File "/Users/Scoring/Desktop/rabbit-bot/venv/lib/python3.11/site-packages/aiogram/utils/executor.py", line 45, in start_polling
    executor.start_polling(
  File "/Users/Scoring/Desktop/rabbit-bot/venv/lib/python3.11/site-packages/aiogram/utils/executor.py", line 328, in start_polling
    loop.run_until_complete(self._shutdown_polling())
  File "/Library/Frameworks/Python.framework/Versions/3.11/lib/python3.11/asyncio/base_events.py", line 640, in run_until_complete
    self.run_forever()
  File "/Library/Frameworks/Python.framework/Versions/3.11/lib/python3.11/asyncio/base_events.py", line 607, in run_forever
    self._run_once()
  File "/Library/Frameworks/Python.framework/Versions/3.11/lib/python3.11/asyncio/base_events.py", line 1919, in _run_once
    handle._run()
  File "/Library/Frameworks/Python.framework/Versions/3.11/lib/python3.11/asyncio/events.py", line 80, in _run
    self._context.run(self._callback, *self._args)
  File "/Users/Scoring/Desktop/rabbit-bot/venv/lib/python3.11/site-packages/aiogram/dispatcher/dispatcher.py", line 415, in _process_polling_updates
    for responses in itertools.chain.from_iterable(await self.process_updates(updates, fast)):
                                                   ^^^^^^^^^^^^^^^^^^^^^^^^^^^^^^^^^^^^^^^^^
  File "/Users/Scoring/Desktop/rabbit-bot/venv/lib/python3.11/site-packages/aiogram/dispatcher/dispatcher.py", line 235, in process_updates
    return await asyncio.gather(*tasks)
           ^^^^^^^^^^^^^^^^^^^^^^^^^^^^
  File "/Users/Scoring/Desktop/rabbit-bot/venv/lib/python3.11/site-packages/aiogram/utils/executor.py", line 323, in start_polling
    loop.run_forever()
  File "/Library/Frameworks/Python.framework/Versions/3.11/lib/python3.11/asyncio/base_events.py", line 607, in run_forever
    self._run_once()
  File "/Library/Frameworks/Python.framework/Versions/3.11/lib/python3.11/asyncio/base_events.py", line 1919, in _run_once
    handle._run()
  File "/Library/Frameworks/Python.framework/Versions/3.11/lib/python3.11/asyncio/events.py", line 80, in _run
    self._context.run(self._callback, *self._args)
  File "/Users/Scoring/Desktop/rabbit-bot/venv/lib/python3.11/site-packages/aiogram/dispatcher/handler.py", line 117, in notify
    response = await handler_obj.handler(*args, **partial_data)
               ^^^^^^^^^^^^^^^^^^^^^^^^^^^^^^^^^^^^^^^^^^^^^^^^
  File "/Users/Scoring/Desktop/rabbit-bot/venv/lib/python3.11/site-packages/aiogram/dispatcher/dispatcher.py", line 256, in process_update
    return await self.message_handlers.notify(update.message)
           ^^^^^^^^^^^^^^^^^^^^^^^^^^^^^^^^^^^^^^^^^^^^^^^^^^
  File "/Users/Scoring/Desktop/rabbit-bot/venv/lib/python3.11/site-packages/aiogram/dispatcher/handler.py", line 117, in notify
    response = await handler_obj.handler(*args, **partial_data)
               ^^^^^^^^^^^^^^^^^^^^^^^^^^^^^^^^^^^^^^^^^^^^^^^^
  File "/Users/Scoring/Desktop/rabbit-bot/command.py", line 635, in handle_delete_message
    await delete_message(message_id_to_delete, message, admins)
  File "/Users/Scoring/Desktop/rabbit-bot/command.py", line 641, in delete_message
    message_details = messages_ref.child(message_id).get()
                      ^^^^^^^^^^^^^^^^^^^^^^^^^^^^^^^^^^^^
  File "/Users/Scoring/Desktop/rabbit-bot/venv/lib/python3.11/site-packages/firebase_admin/db.py", line 221, in get
    return self._client.body('get', self._add_suffix(), params=params)
           ^^^^^^^^^^^^^^^^^^^^^^^^^^^^^^^^^^^^^^^^^^^^^^^^^^^^^^^^^^^
  File "/Users/Scoring/Desktop/rabbit-bot/venv/lib/python3.11/site-packages/firebase_admin/_http_client.py", line 131, in body
    resp = self.request(method, url, **kwargs)
           ^^^^^^^^^^^^^^^^^^^^^^^^^^^^^^^^^^^
  File "/Users/Scoring/Desktop/rabbit-bot/venv/lib/python3.11/site-packages/firebase_admin/db.py", line 929, in request
    return super(_Client, self).request(method, url, **kwargs)
           ^^^^^^^^^^^^^^^^^^^^^^^^^^^^^^^^^^^^^^^^^^^^^^^^^^^
  File "/Users/Scoring/Desktop/rabbit-bot/venv/lib/python3.11/site-packages/firebase_admin/_http_client.py", line 118, in request
    resp = self._session.request(method, self.base_url + url, **kwargs)
           ^^^^^^^^^^^^^^^^^^^^^^^^^^^^^^^^^^^^^^^^^^^^^^^^^^^^^^^^^^^^
  File "/Users/Scoring/Desktop/rabbit-bot/venv/lib/python3.11/site-packages/google/auth/transport/requests.py", line 534, in request
    self.credentials.before_request(auth_request, method, url, request_headers)
  File "/Users/Scoring/Desktop/rabbit-bot/venv/lib/python3.11/site-packages/google/auth/credentials.py", line 239, in before_request
    self._blocking_refresh(request)
  File "/Users/Scoring/Desktop/rabbit-bot/venv/lib/python3.11/site-packages/google/auth/credentials.py", line 202, in _blocking_refresh
    self.refresh(request)
  File "/Users/Scoring/Desktop/rabbit-bot/venv/lib/python3.11/site-packages/google/oauth2/service_account.py", line 448, in refresh
    access_token, expiry, _ = _client.jwt_grant(
                              ^^^^^^^^^^^^^^^^^^
  File "/Users/Scoring/Desktop/rabbit-bot/venv/lib/python3.11/site-packages/google/oauth2/_client.py", line 298, in jwt_grant
    response_data = _token_endpoint_request(
                    ^^^^^^^^^^^^^^^^^^^^^^^^
  File "/Users/Scoring/Desktop/rabbit-bot/venv/lib/python3.11/site-packages/google/oauth2/_client.py", line 258, in _token_endpoint_request
    response_status_ok, response_data, retryable_error = _token_endpoint_request_no_throw(
                                                         ^^^^^^^^^^^^^^^^^^^^^^^^^^^^^^^^^
  File "/Users/Scoring/Desktop/rabbit-bot/venv/lib/python3.11/site-packages/google/oauth2/_client.py", line 191, in _token_endpoint_request_no_throw
    response = request(
               ^^^^^^^^
  File "/Users/Scoring/Desktop/rabbit-bot/venv/lib/python3.11/site-packages/google/auth/transport/requests.py", line 187, in __call__
    response = self.session.request(
               ^^^^^^^^^^^^^^^^^^^^^
  File "/Users/Scoring/Desktop/rabbit-bot/venv/lib/python3.11/site-packages/requests/sessions.py", line 589, in request
    resp = self.send(prep, **send_kwargs)
           ^^^^^^^^^^^^^^^^^^^^^^^^^^^^^^
  File "/Users/Scoring/Desktop/rabbit-bot/venv/lib/python3.11/site-packages/requests/sessions.py", line 703, in send
    r = adapter.send(request, **kwargs)
        ^^^^^^^^^^^^^^^^^^^^^^^^^^^^^^^
  File "/Users/Scoring/Desktop/rabbit-bot/venv/lib/python3.11/site-packages/requests/adapters.py", line 667, in send
    resp = conn.urlopen(
           ^^^^^^^^^^^^^
  File "/Users/Scoring/Desktop/rabbit-bot/venv/lib/python3.11/site-packages/urllib3/connectionpool.py", line 789, in urlopen
    response = self._make_request(
               ^^^^^^^^^^^^^^^^^^^
  File "/Users/Scoring/Desktop/rabbit-bot/venv/lib/python3.11/site-packages/urllib3/connectionpool.py", line 466, in _make_request
    self._validate_conn(conn)
  File "/Users/Scoring/Desktop/rabbit-bot/venv/lib/python3.11/site-packages/urllib3/connectionpool.py", line 1095, in _validate_conn
    conn.connect()
  File "/Users/Scoring/Desktop/rabbit-bot/venv/lib/python3.11/site-packages/urllib3/connection.py", line 693, in connect
    self.sock = sock = self._new_conn()
                       ^^^^^^^^^^^^^^^^
  File "/Users/Scoring/Desktop/rabbit-bot/venv/lib/python3.11/site-packages/urllib3/connection.py", line 206, in _new_conn
    raise NameResolutionError(self.host, self, e) from e
                              ^^^^^^^^^
  File "/Users/Scoring/Desktop/rabbit-bot/venv/lib/python3.11/site-packages/urllib3/connection.py", line 164, in host
    @property
    
KeyboardInterrupt
2024-11-04 21:30:35,533 - INFO - Bot: RabbitHole Bot [@rabbit4ogs_bot]
2024-11-04 21:30:35,962 - WARNING - Updates were skipped successfully.
2024-11-04 21:30:35,963 - INFO - Start polling.
2024-11-04 21:30:54,994 - WARNING - Retrying (Retry(total=9, connect=0, read=1, redirect=None, status=4)) after connection broken by 'NameResolutionError("<urllib3.connection.HTTPSConnection object at 0x10c3fc050>: Failed to resolve 'rabbitbot-9afc1-default-rtdb.firebaseio.com' ([Errno 8] nodename nor servname provided, or not known)")': /users/1424693218.json
2024-11-04 21:30:55,019 - ERROR - Task exception was never retrieved
future: <Task finished name='Task-9' coro=<Dispatcher._process_polling_updates() done, defined at /Users/Scoring/Desktop/rabbit-bot/venv/lib/python3.11/site-packages/aiogram/dispatcher/dispatcher.py:407> exception=UnavailableError('Failed to establish a connection: HTTPSConnectionPool(host=\'rabbitbot-9afc1-default-rtdb.firebaseio.com\', port=443): Max retries exceeded with url: /users/1424693218.json (Caused by NameResolutionError("<urllib3.connection.HTTPSConnection object at 0x10c3fc890>: Failed to resolve \'rabbitbot-9afc1-default-rtdb.firebaseio.com\' ([Errno 8] nodename nor servname provided, or not known)"))')>
Traceback (most recent call last):
  File "/Users/Scoring/Desktop/rabbit-bot/venv/lib/python3.11/site-packages/urllib3/connection.py", line 199, in _new_conn
    sock = connection.create_connection(
           ^^^^^^^^^^^^^^^^^^^^^^^^^^^^^
  File "/Users/Scoring/Desktop/rabbit-bot/venv/lib/python3.11/site-packages/urllib3/util/connection.py", line 60, in create_connection
    for res in socket.getaddrinfo(host, port, family, socket.SOCK_STREAM):
               ^^^^^^^^^^^^^^^^^^^^^^^^^^^^^^^^^^^^^^^^^^^^^^^^^^^^^^^^^^
  File "/Library/Frameworks/Python.framework/Versions/3.11/lib/python3.11/socket.py", line 962, in getaddrinfo
    for res in _socket.getaddrinfo(host, port, family, type, proto, flags):
               ^^^^^^^^^^^^^^^^^^^^^^^^^^^^^^^^^^^^^^^^^^^^^^^^^^^^^^^^^^^
socket.gaierror: [Errno 8] nodename nor servname provided, or not known

The above exception was the direct cause of the following exception:

Traceback (most recent call last):
  File "/Users/Scoring/Desktop/rabbit-bot/venv/lib/python3.11/site-packages/urllib3/connectionpool.py", line 789, in urlopen
    response = self._make_request(
               ^^^^^^^^^^^^^^^^^^^
  File "/Users/Scoring/Desktop/rabbit-bot/venv/lib/python3.11/site-packages/urllib3/connectionpool.py", line 490, in _make_request
    raise new_e
  File "/Users/Scoring/Desktop/rabbit-bot/venv/lib/python3.11/site-packages/urllib3/connectionpool.py", line 466, in _make_request
    self._validate_conn(conn)
  File "/Users/Scoring/Desktop/rabbit-bot/venv/lib/python3.11/site-packages/urllib3/connectionpool.py", line 1095, in _validate_conn
    conn.connect()
  File "/Users/Scoring/Desktop/rabbit-bot/venv/lib/python3.11/site-packages/urllib3/connection.py", line 693, in connect
    self.sock = sock = self._new_conn()
                       ^^^^^^^^^^^^^^^^
  File "/Users/Scoring/Desktop/rabbit-bot/venv/lib/python3.11/site-packages/urllib3/connection.py", line 206, in _new_conn
    raise NameResolutionError(self.host, self, e) from e
urllib3.exceptions.NameResolutionError: <urllib3.connection.HTTPSConnection object at 0x10c3fc890>: Failed to resolve 'rabbitbot-9afc1-default-rtdb.firebaseio.com' ([Errno 8] nodename nor servname provided, or not known)

The above exception was the direct cause of the following exception:

Traceback (most recent call last):
  File "/Users/Scoring/Desktop/rabbit-bot/venv/lib/python3.11/site-packages/requests/adapters.py", line 667, in send
    resp = conn.urlopen(
           ^^^^^^^^^^^^^
  File "/Users/Scoring/Desktop/rabbit-bot/venv/lib/python3.11/site-packages/urllib3/connectionpool.py", line 873, in urlopen
    return self.urlopen(
           ^^^^^^^^^^^^^
  File "/Users/Scoring/Desktop/rabbit-bot/venv/lib/python3.11/site-packages/urllib3/connectionpool.py", line 843, in urlopen
    retries = retries.increment(
              ^^^^^^^^^^^^^^^^^^
  File "/Users/Scoring/Desktop/rabbit-bot/venv/lib/python3.11/site-packages/urllib3/util/retry.py", line 519, in increment
    raise MaxRetryError(_pool, url, reason) from reason  # type: ignore[arg-type]
    ^^^^^^^^^^^^^^^^^^^^^^^^^^^^^^^^^^^^^^^^^^^^^^^^^^^
urllib3.exceptions.MaxRetryError: HTTPSConnectionPool(host='rabbitbot-9afc1-default-rtdb.firebaseio.com', port=443): Max retries exceeded with url: /users/1424693218.json (Caused by NameResolutionError("<urllib3.connection.HTTPSConnection object at 0x10c3fc890>: Failed to resolve 'rabbitbot-9afc1-default-rtdb.firebaseio.com' ([Errno 8] nodename nor servname provided, or not known)"))

During handling of the above exception, another exception occurred:

Traceback (most recent call last):
  File "/Users/Scoring/Desktop/rabbit-bot/venv/lib/python3.11/site-packages/firebase_admin/db.py", line 929, in request
    return super(_Client, self).request(method, url, **kwargs)
           ^^^^^^^^^^^^^^^^^^^^^^^^^^^^^^^^^^^^^^^^^^^^^^^^^^^
  File "/Users/Scoring/Desktop/rabbit-bot/venv/lib/python3.11/site-packages/firebase_admin/_http_client.py", line 118, in request
    resp = self._session.request(method, self.base_url + url, **kwargs)
           ^^^^^^^^^^^^^^^^^^^^^^^^^^^^^^^^^^^^^^^^^^^^^^^^^^^^^^^^^^^^
  File "/Users/Scoring/Desktop/rabbit-bot/venv/lib/python3.11/site-packages/google/auth/transport/requests.py", line 538, in request
    response = super(AuthorizedSession, self).request(
               ^^^^^^^^^^^^^^^^^^^^^^^^^^^^^^^^^^^^^^^
  File "/Users/Scoring/Desktop/rabbit-bot/venv/lib/python3.11/site-packages/requests/sessions.py", line 589, in request
    resp = self.send(prep, **send_kwargs)
           ^^^^^^^^^^^^^^^^^^^^^^^^^^^^^^
  File "/Users/Scoring/Desktop/rabbit-bot/venv/lib/python3.11/site-packages/requests/sessions.py", line 703, in send
    r = adapter.send(request, **kwargs)
        ^^^^^^^^^^^^^^^^^^^^^^^^^^^^^^^
  File "/Users/Scoring/Desktop/rabbit-bot/venv/lib/python3.11/site-packages/requests/adapters.py", line 700, in send
    raise ConnectionError(e, request=request)
requests.exceptions.ConnectionError: HTTPSConnectionPool(host='rabbitbot-9afc1-default-rtdb.firebaseio.com', port=443): Max retries exceeded with url: /users/1424693218.json (Caused by NameResolutionError("<urllib3.connection.HTTPSConnection object at 0x10c3fc890>: Failed to resolve 'rabbitbot-9afc1-default-rtdb.firebaseio.com' ([Errno 8] nodename nor servname provided, or not known)"))

During handling of the above exception, another exception occurred:

Traceback (most recent call last):
  File "/Users/Scoring/Desktop/rabbit-bot/venv/lib/python3.11/site-packages/aiogram/dispatcher/dispatcher.py", line 415, in _process_polling_updates
    for responses in itertools.chain.from_iterable(await self.process_updates(updates, fast)):
                                                   ^^^^^^^^^^^^^^^^^^^^^^^^^^^^^^^^^^^^^^^^^
  File "/Users/Scoring/Desktop/rabbit-bot/venv/lib/python3.11/site-packages/aiogram/dispatcher/dispatcher.py", line 235, in process_updates
    return await asyncio.gather(*tasks)
           ^^^^^^^^^^^^^^^^^^^^^^^^^^^^
  File "/Users/Scoring/Desktop/rabbit-bot/venv/lib/python3.11/site-packages/aiogram/dispatcher/handler.py", line 117, in notify
    response = await handler_obj.handler(*args, **partial_data)
               ^^^^^^^^^^^^^^^^^^^^^^^^^^^^^^^^^^^^^^^^^^^^^^^^
  File "/Users/Scoring/Desktop/rabbit-bot/venv/lib/python3.11/site-packages/aiogram/dispatcher/dispatcher.py", line 256, in process_update
    return await self.message_handlers.notify(update.message)
           ^^^^^^^^^^^^^^^^^^^^^^^^^^^^^^^^^^^^^^^^^^^^^^^^^^
  File "/Users/Scoring/Desktop/rabbit-bot/venv/lib/python3.11/site-packages/aiogram/dispatcher/handler.py", line 117, in notify
    response = await handler_obj.handler(*args, **partial_data)
               ^^^^^^^^^^^^^^^^^^^^^^^^^^^^^^^^^^^^^^^^^^^^^^^^
  File "/Users/Scoring/Desktop/rabbit-bot/command.py", line 56, in display_profile
    user_data = user_ref.get()
                ^^^^^^^^^^^^^^
  File "/Users/Scoring/Desktop/rabbit-bot/venv/lib/python3.11/site-packages/firebase_admin/db.py", line 221, in get
    return self._client.body('get', self._add_suffix(), params=params)
           ^^^^^^^^^^^^^^^^^^^^^^^^^^^^^^^^^^^^^^^^^^^^^^^^^^^^^^^^^^^
  File "/Users/Scoring/Desktop/rabbit-bot/venv/lib/python3.11/site-packages/firebase_admin/_http_client.py", line 131, in body
    resp = self.request(method, url, **kwargs)
           ^^^^^^^^^^^^^^^^^^^^^^^^^^^^^^^^^^^
  File "/Users/Scoring/Desktop/rabbit-bot/venv/lib/python3.11/site-packages/firebase_admin/db.py", line 931, in request
    raise _Client.handle_rtdb_error(error)
firebase_admin.exceptions.UnavailableError: Failed to establish a connection: HTTPSConnectionPool(host='rabbitbot-9afc1-default-rtdb.firebaseio.com', port=443): Max retries exceeded with url: /users/1424693218.json (Caused by NameResolutionError("<urllib3.connection.HTTPSConnection object at 0x10c3fc890>: Failed to resolve 'rabbitbot-9afc1-default-rtdb.firebaseio.com' ([Errno 8] nodename nor servname provided, or not known)"))
2024-11-04 21:31:06,558 - WARNING - Retrying (Retry(total=9, connect=0, read=1, redirect=None, status=4)) after connection broken by 'NameResolutionError("<urllib3.connection.HTTPSConnection object at 0x10c4ccb50>: Failed to resolve 'rabbitbot-9afc1-default-rtdb.firebaseio.com' ([Errno 8] nodename nor servname provided, or not known)")': /users/1424693218.json
2024-11-04 21:31:06,564 - ERROR - Task exception was never retrieved
future: <Task finished name='Task-18' coro=<Dispatcher._process_polling_updates() done, defined at /Users/Scoring/Desktop/rabbit-bot/venv/lib/python3.11/site-packages/aiogram/dispatcher/dispatcher.py:407> exception=UnavailableError('Failed to establish a connection: HTTPSConnectionPool(host=\'rabbitbot-9afc1-default-rtdb.firebaseio.com\', port=443): Max retries exceeded with url: /users/1424693218.json (Caused by NameResolutionError("<urllib3.connection.HTTPSConnection object at 0x10c4cd510>: Failed to resolve \'rabbitbot-9afc1-default-rtdb.firebaseio.com\' ([Errno 8] nodename nor servname provided, or not known)"))')>
Traceback (most recent call last):
  File "/Users/Scoring/Desktop/rabbit-bot/venv/lib/python3.11/site-packages/urllib3/connection.py", line 199, in _new_conn
    sock = connection.create_connection(
           ^^^^^^^^^^^^^^^^^^^^^^^^^^^^^
  File "/Users/Scoring/Desktop/rabbit-bot/venv/lib/python3.11/site-packages/urllib3/util/connection.py", line 60, in create_connection
    for res in socket.getaddrinfo(host, port, family, socket.SOCK_STREAM):
               ^^^^^^^^^^^^^^^^^^^^^^^^^^^^^^^^^^^^^^^^^^^^^^^^^^^^^^^^^^
  File "/Library/Frameworks/Python.framework/Versions/3.11/lib/python3.11/socket.py", line 962, in getaddrinfo
    for res in _socket.getaddrinfo(host, port, family, type, proto, flags):
               ^^^^^^^^^^^^^^^^^^^^^^^^^^^^^^^^^^^^^^^^^^^^^^^^^^^^^^^^^^^
socket.gaierror: [Errno 8] nodename nor servname provided, or not known

The above exception was the direct cause of the following exception:

Traceback (most recent call last):
  File "/Users/Scoring/Desktop/rabbit-bot/venv/lib/python3.11/site-packages/urllib3/connectionpool.py", line 789, in urlopen
    response = self._make_request(
               ^^^^^^^^^^^^^^^^^^^
  File "/Users/Scoring/Desktop/rabbit-bot/venv/lib/python3.11/site-packages/urllib3/connectionpool.py", line 490, in _make_request
    raise new_e
  File "/Users/Scoring/Desktop/rabbit-bot/venv/lib/python3.11/site-packages/urllib3/connectionpool.py", line 466, in _make_request
    self._validate_conn(conn)
  File "/Users/Scoring/Desktop/rabbit-bot/venv/lib/python3.11/site-packages/urllib3/connectionpool.py", line 1095, in _validate_conn
    conn.connect()
  File "/Users/Scoring/Desktop/rabbit-bot/venv/lib/python3.11/site-packages/urllib3/connection.py", line 693, in connect
    self.sock = sock = self._new_conn()
                       ^^^^^^^^^^^^^^^^
  File "/Users/Scoring/Desktop/rabbit-bot/venv/lib/python3.11/site-packages/urllib3/connection.py", line 206, in _new_conn
    raise NameResolutionError(self.host, self, e) from e
urllib3.exceptions.NameResolutionError: <urllib3.connection.HTTPSConnection object at 0x10c4cd510>: Failed to resolve 'rabbitbot-9afc1-default-rtdb.firebaseio.com' ([Errno 8] nodename nor servname provided, or not known)

The above exception was the direct cause of the following exception:

Traceback (most recent call last):
  File "/Users/Scoring/Desktop/rabbit-bot/venv/lib/python3.11/site-packages/requests/adapters.py", line 667, in send
    resp = conn.urlopen(
           ^^^^^^^^^^^^^
  File "/Users/Scoring/Desktop/rabbit-bot/venv/lib/python3.11/site-packages/urllib3/connectionpool.py", line 873, in urlopen
    return self.urlopen(
           ^^^^^^^^^^^^^
  File "/Users/Scoring/Desktop/rabbit-bot/venv/lib/python3.11/site-packages/urllib3/connectionpool.py", line 843, in urlopen
    retries = retries.increment(
              ^^^^^^^^^^^^^^^^^^
  File "/Users/Scoring/Desktop/rabbit-bot/venv/lib/python3.11/site-packages/urllib3/util/retry.py", line 519, in increment
    raise MaxRetryError(_pool, url, reason) from reason  # type: ignore[arg-type]
    ^^^^^^^^^^^^^^^^^^^^^^^^^^^^^^^^^^^^^^^^^^^^^^^^^^^
urllib3.exceptions.MaxRetryError: HTTPSConnectionPool(host='rabbitbot-9afc1-default-rtdb.firebaseio.com', port=443): Max retries exceeded with url: /users/1424693218.json (Caused by NameResolutionError("<urllib3.connection.HTTPSConnection object at 0x10c4cd510>: Failed to resolve 'rabbitbot-9afc1-default-rtdb.firebaseio.com' ([Errno 8] nodename nor servname provided, or not known)"))

During handling of the above exception, another exception occurred:

Traceback (most recent call last):
  File "/Users/Scoring/Desktop/rabbit-bot/venv/lib/python3.11/site-packages/firebase_admin/db.py", line 929, in request
    return super(_Client, self).request(method, url, **kwargs)
           ^^^^^^^^^^^^^^^^^^^^^^^^^^^^^^^^^^^^^^^^^^^^^^^^^^^
  File "/Users/Scoring/Desktop/rabbit-bot/venv/lib/python3.11/site-packages/firebase_admin/_http_client.py", line 118, in request
    resp = self._session.request(method, self.base_url + url, **kwargs)
           ^^^^^^^^^^^^^^^^^^^^^^^^^^^^^^^^^^^^^^^^^^^^^^^^^^^^^^^^^^^^
  File "/Users/Scoring/Desktop/rabbit-bot/venv/lib/python3.11/site-packages/google/auth/transport/requests.py", line 538, in request
    response = super(AuthorizedSession, self).request(
               ^^^^^^^^^^^^^^^^^^^^^^^^^^^^^^^^^^^^^^^
  File "/Users/Scoring/Desktop/rabbit-bot/venv/lib/python3.11/site-packages/requests/sessions.py", line 589, in request
    resp = self.send(prep, **send_kwargs)
           ^^^^^^^^^^^^^^^^^^^^^^^^^^^^^^
  File "/Users/Scoring/Desktop/rabbit-bot/venv/lib/python3.11/site-packages/requests/sessions.py", line 703, in send
    r = adapter.send(request, **kwargs)
        ^^^^^^^^^^^^^^^^^^^^^^^^^^^^^^^
  File "/Users/Scoring/Desktop/rabbit-bot/venv/lib/python3.11/site-packages/requests/adapters.py", line 700, in send
    raise ConnectionError(e, request=request)
requests.exceptions.ConnectionError: HTTPSConnectionPool(host='rabbitbot-9afc1-default-rtdb.firebaseio.com', port=443): Max retries exceeded with url: /users/1424693218.json (Caused by NameResolutionError("<urllib3.connection.HTTPSConnection object at 0x10c4cd510>: Failed to resolve 'rabbitbot-9afc1-default-rtdb.firebaseio.com' ([Errno 8] nodename nor servname provided, or not known)"))

During handling of the above exception, another exception occurred:

Traceback (most recent call last):
  File "/Users/Scoring/Desktop/rabbit-bot/venv/lib/python3.11/site-packages/aiogram/dispatcher/dispatcher.py", line 415, in _process_polling_updates
    for responses in itertools.chain.from_iterable(await self.process_updates(updates, fast)):
                                                   ^^^^^^^^^^^^^^^^^^^^^^^^^^^^^^^^^^^^^^^^^
  File "/Users/Scoring/Desktop/rabbit-bot/venv/lib/python3.11/site-packages/aiogram/dispatcher/dispatcher.py", line 235, in process_updates
    return await asyncio.gather(*tasks)
           ^^^^^^^^^^^^^^^^^^^^^^^^^^^^
  File "/Users/Scoring/Desktop/rabbit-bot/venv/lib/python3.11/site-packages/aiogram/dispatcher/handler.py", line 117, in notify
    response = await handler_obj.handler(*args, **partial_data)
               ^^^^^^^^^^^^^^^^^^^^^^^^^^^^^^^^^^^^^^^^^^^^^^^^
  File "/Users/Scoring/Desktop/rabbit-bot/venv/lib/python3.11/site-packages/aiogram/dispatcher/dispatcher.py", line 256, in process_update
    return await self.message_handlers.notify(update.message)
           ^^^^^^^^^^^^^^^^^^^^^^^^^^^^^^^^^^^^^^^^^^^^^^^^^^
  File "/Users/Scoring/Desktop/rabbit-bot/venv/lib/python3.11/site-packages/aiogram/dispatcher/handler.py", line 117, in notify
    response = await handler_obj.handler(*args, **partial_data)
               ^^^^^^^^^^^^^^^^^^^^^^^^^^^^^^^^^^^^^^^^^^^^^^^^
  File "/Users/Scoring/Desktop/rabbit-bot/command.py", line 56, in display_profile
    user_data = user_ref.get()
                ^^^^^^^^^^^^^^
  File "/Users/Scoring/Desktop/rabbit-bot/venv/lib/python3.11/site-packages/firebase_admin/db.py", line 221, in get
    return self._client.body('get', self._add_suffix(), params=params)
           ^^^^^^^^^^^^^^^^^^^^^^^^^^^^^^^^^^^^^^^^^^^^^^^^^^^^^^^^^^^
  File "/Users/Scoring/Desktop/rabbit-bot/venv/lib/python3.11/site-packages/firebase_admin/_http_client.py", line 131, in body
    resp = self.request(method, url, **kwargs)
           ^^^^^^^^^^^^^^^^^^^^^^^^^^^^^^^^^^^
  File "/Users/Scoring/Desktop/rabbit-bot/venv/lib/python3.11/site-packages/firebase_admin/db.py", line 931, in request
    raise _Client.handle_rtdb_error(error)
firebase_admin.exceptions.UnavailableError: Failed to establish a connection: HTTPSConnectionPool(host='rabbitbot-9afc1-default-rtdb.firebaseio.com', port=443): Max retries exceeded with url: /users/1424693218.json (Caused by NameResolutionError("<urllib3.connection.HTTPSConnection object at 0x10c4cd510>: Failed to resolve 'rabbitbot-9afc1-default-rtdb.firebaseio.com' ([Errno 8] nodename nor servname provided, or not known)"))
2024-11-04 21:31:21,633 - WARNING - Retrying (Retry(total=9, connect=0, read=1, redirect=None, status=4)) after connection broken by 'NameResolutionError("<urllib3.connection.HTTPSConnection object at 0x10c4d8790>: Failed to resolve 'rabbitbot-9afc1-default-rtdb.firebaseio.com' ([Errno 8] nodename nor servname provided, or not known)")': /products.json
2024-11-04 21:31:21,635 - ERROR - Task exception was never retrieved
future: <Task finished name='Task-25' coro=<Dispatcher._process_polling_updates() done, defined at /Users/Scoring/Desktop/rabbit-bot/venv/lib/python3.11/site-packages/aiogram/dispatcher/dispatcher.py:407> exception=UnavailableError('Failed to establish a connection: HTTPSConnectionPool(host=\'rabbitbot-9afc1-default-rtdb.firebaseio.com\', port=443): Max retries exceeded with url: /products.json (Caused by NameResolutionError("<urllib3.connection.HTTPSConnection object at 0x10c4d9050>: Failed to resolve \'rabbitbot-9afc1-default-rtdb.firebaseio.com\' ([Errno 8] nodename nor servname provided, or not known)"))')>
Traceback (most recent call last):
  File "/Users/Scoring/Desktop/rabbit-bot/venv/lib/python3.11/site-packages/urllib3/connection.py", line 199, in _new_conn
    sock = connection.create_connection(
           ^^^^^^^^^^^^^^^^^^^^^^^^^^^^^
  File "/Users/Scoring/Desktop/rabbit-bot/venv/lib/python3.11/site-packages/urllib3/util/connection.py", line 60, in create_connection
    for res in socket.getaddrinfo(host, port, family, socket.SOCK_STREAM):
               ^^^^^^^^^^^^^^^^^^^^^^^^^^^^^^^^^^^^^^^^^^^^^^^^^^^^^^^^^^
  File "/Library/Frameworks/Python.framework/Versions/3.11/lib/python3.11/socket.py", line 962, in getaddrinfo
    for res in _socket.getaddrinfo(host, port, family, type, proto, flags):
               ^^^^^^^^^^^^^^^^^^^^^^^^^^^^^^^^^^^^^^^^^^^^^^^^^^^^^^^^^^^
socket.gaierror: [Errno 8] nodename nor servname provided, or not known

The above exception was the direct cause of the following exception:

Traceback (most recent call last):
  File "/Users/Scoring/Desktop/rabbit-bot/venv/lib/python3.11/site-packages/urllib3/connectionpool.py", line 789, in urlopen
    response = self._make_request(
               ^^^^^^^^^^^^^^^^^^^
  File "/Users/Scoring/Desktop/rabbit-bot/venv/lib/python3.11/site-packages/urllib3/connectionpool.py", line 490, in _make_request
    raise new_e
  File "/Users/Scoring/Desktop/rabbit-bot/venv/lib/python3.11/site-packages/urllib3/connectionpool.py", line 466, in _make_request
    self._validate_conn(conn)
  File "/Users/Scoring/Desktop/rabbit-bot/venv/lib/python3.11/site-packages/urllib3/connectionpool.py", line 1095, in _validate_conn
    conn.connect()
  File "/Users/Scoring/Desktop/rabbit-bot/venv/lib/python3.11/site-packages/urllib3/connection.py", line 693, in connect
    self.sock = sock = self._new_conn()
                       ^^^^^^^^^^^^^^^^
  File "/Users/Scoring/Desktop/rabbit-bot/venv/lib/python3.11/site-packages/urllib3/connection.py", line 206, in _new_conn
    raise NameResolutionError(self.host, self, e) from e
urllib3.exceptions.NameResolutionError: <urllib3.connection.HTTPSConnection object at 0x10c4d9050>: Failed to resolve 'rabbitbot-9afc1-default-rtdb.firebaseio.com' ([Errno 8] nodename nor servname provided, or not known)

The above exception was the direct cause of the following exception:

Traceback (most recent call last):
  File "/Users/Scoring/Desktop/rabbit-bot/venv/lib/python3.11/site-packages/requests/adapters.py", line 667, in send
    resp = conn.urlopen(
           ^^^^^^^^^^^^^
  File "/Users/Scoring/Desktop/rabbit-bot/venv/lib/python3.11/site-packages/urllib3/connectionpool.py", line 873, in urlopen
    return self.urlopen(
           ^^^^^^^^^^^^^
  File "/Users/Scoring/Desktop/rabbit-bot/venv/lib/python3.11/site-packages/urllib3/connectionpool.py", line 843, in urlopen
    retries = retries.increment(
              ^^^^^^^^^^^^^^^^^^
  File "/Users/Scoring/Desktop/rabbit-bot/venv/lib/python3.11/site-packages/urllib3/util/retry.py", line 519, in increment
    raise MaxRetryError(_pool, url, reason) from reason  # type: ignore[arg-type]
    ^^^^^^^^^^^^^^^^^^^^^^^^^^^^^^^^^^^^^^^^^^^^^^^^^^^
urllib3.exceptions.MaxRetryError: HTTPSConnectionPool(host='rabbitbot-9afc1-default-rtdb.firebaseio.com', port=443): Max retries exceeded with url: /products.json (Caused by NameResolutionError("<urllib3.connection.HTTPSConnection object at 0x10c4d9050>: Failed to resolve 'rabbitbot-9afc1-default-rtdb.firebaseio.com' ([Errno 8] nodename nor servname provided, or not known)"))

During handling of the above exception, another exception occurred:

Traceback (most recent call last):
  File "/Users/Scoring/Desktop/rabbit-bot/venv/lib/python3.11/site-packages/firebase_admin/db.py", line 929, in request
    return super(_Client, self).request(method, url, **kwargs)
           ^^^^^^^^^^^^^^^^^^^^^^^^^^^^^^^^^^^^^^^^^^^^^^^^^^^
  File "/Users/Scoring/Desktop/rabbit-bot/venv/lib/python3.11/site-packages/firebase_admin/_http_client.py", line 118, in request
    resp = self._session.request(method, self.base_url + url, **kwargs)
           ^^^^^^^^^^^^^^^^^^^^^^^^^^^^^^^^^^^^^^^^^^^^^^^^^^^^^^^^^^^^
  File "/Users/Scoring/Desktop/rabbit-bot/venv/lib/python3.11/site-packages/google/auth/transport/requests.py", line 538, in request
    response = super(AuthorizedSession, self).request(
               ^^^^^^^^^^^^^^^^^^^^^^^^^^^^^^^^^^^^^^^
  File "/Users/Scoring/Desktop/rabbit-bot/venv/lib/python3.11/site-packages/requests/sessions.py", line 589, in request
    resp = self.send(prep, **send_kwargs)
           ^^^^^^^^^^^^^^^^^^^^^^^^^^^^^^
  File "/Users/Scoring/Desktop/rabbit-bot/venv/lib/python3.11/site-packages/requests/sessions.py", line 703, in send
    r = adapter.send(request, **kwargs)
        ^^^^^^^^^^^^^^^^^^^^^^^^^^^^^^^
  File "/Users/Scoring/Desktop/rabbit-bot/venv/lib/python3.11/site-packages/requests/adapters.py", line 700, in send
    raise ConnectionError(e, request=request)
requests.exceptions.ConnectionError: HTTPSConnectionPool(host='rabbitbot-9afc1-default-rtdb.firebaseio.com', port=443): Max retries exceeded with url: /products.json (Caused by NameResolutionError("<urllib3.connection.HTTPSConnection object at 0x10c4d9050>: Failed to resolve 'rabbitbot-9afc1-default-rtdb.firebaseio.com' ([Errno 8] nodename nor servname provided, or not known)"))

During handling of the above exception, another exception occurred:

Traceback (most recent call last):
  File "/Users/Scoring/Desktop/rabbit-bot/venv/lib/python3.11/site-packages/aiogram/dispatcher/dispatcher.py", line 415, in _process_polling_updates
    for responses in itertools.chain.from_iterable(await self.process_updates(updates, fast)):
                                                   ^^^^^^^^^^^^^^^^^^^^^^^^^^^^^^^^^^^^^^^^^
  File "/Users/Scoring/Desktop/rabbit-bot/venv/lib/python3.11/site-packages/aiogram/dispatcher/dispatcher.py", line 235, in process_updates
    return await asyncio.gather(*tasks)
           ^^^^^^^^^^^^^^^^^^^^^^^^^^^^
  File "/Users/Scoring/Desktop/rabbit-bot/venv/lib/python3.11/site-packages/aiogram/dispatcher/handler.py", line 117, in notify
    response = await handler_obj.handler(*args, **partial_data)
               ^^^^^^^^^^^^^^^^^^^^^^^^^^^^^^^^^^^^^^^^^^^^^^^^
  File "/Users/Scoring/Desktop/rabbit-bot/venv/lib/python3.11/site-packages/aiogram/dispatcher/dispatcher.py", line 256, in process_update
    return await self.message_handlers.notify(update.message)
           ^^^^^^^^^^^^^^^^^^^^^^^^^^^^^^^^^^^^^^^^^^^^^^^^^^
  File "/Users/Scoring/Desktop/rabbit-bot/venv/lib/python3.11/site-packages/aiogram/dispatcher/handler.py", line 117, in notify
    response = await handler_obj.handler(*args, **partial_data)
               ^^^^^^^^^^^^^^^^^^^^^^^^^^^^^^^^^^^^^^^^^^^^^^^^
  File "/Users/Scoring/Desktop/rabbit-bot/command.py", line 126, in display_categories
    products_data = products_ref.get()
                    ^^^^^^^^^^^^^^^^^^
  File "/Users/Scoring/Desktop/rabbit-bot/venv/lib/python3.11/site-packages/firebase_admin/db.py", line 221, in get
    return self._client.body('get', self._add_suffix(), params=params)
           ^^^^^^^^^^^^^^^^^^^^^^^^^^^^^^^^^^^^^^^^^^^^^^^^^^^^^^^^^^^
  File "/Users/Scoring/Desktop/rabbit-bot/venv/lib/python3.11/site-packages/firebase_admin/_http_client.py", line 131, in body
    resp = self.request(method, url, **kwargs)
           ^^^^^^^^^^^^^^^^^^^^^^^^^^^^^^^^^^^
  File "/Users/Scoring/Desktop/rabbit-bot/venv/lib/python3.11/site-packages/firebase_admin/db.py", line 931, in request
    raise _Client.handle_rtdb_error(error)
firebase_admin.exceptions.UnavailableError: Failed to establish a connection: HTTPSConnectionPool(host='rabbitbot-9afc1-default-rtdb.firebaseio.com', port=443): Max retries exceeded with url: /products.json (Caused by NameResolutionError("<urllib3.connection.HTTPSConnection object at 0x10c4d9050>: Failed to resolve 'rabbitbot-9afc1-default-rtdb.firebaseio.com' ([Errno 8] nodename nor servname provided, or not known)"))
2024-11-04 21:31:40,895 - WARNING - Retrying (Retry(total=9, connect=0, read=1, redirect=None, status=4)) after connection broken by 'NameResolutionError("<urllib3.connection.HTTPSConnection object at 0x10c4ae590>: Failed to resolve 'rabbitbot-9afc1-default-rtdb.firebaseio.com' ([Errno 8] nodename nor servname provided, or not known)")': /orders.json
2024-11-04 21:31:40,905 - ERROR - Task exception was never retrieved
future: <Task finished name='Task-28' coro=<Dispatcher._process_polling_updates() done, defined at /Users/Scoring/Desktop/rabbit-bot/venv/lib/python3.11/site-packages/aiogram/dispatcher/dispatcher.py:407> exception=UnavailableError('Failed to establish a connection: HTTPSConnectionPool(host=\'rabbitbot-9afc1-default-rtdb.firebaseio.com\', port=443): Max retries exceeded with url: /orders.json (Caused by NameResolutionError("<urllib3.connection.HTTPSConnection object at 0x10c4d9690>: Failed to resolve \'rabbitbot-9afc1-default-rtdb.firebaseio.com\' ([Errno 8] nodename nor servname provided, or not known)"))')>
Traceback (most recent call last):
  File "/Users/Scoring/Desktop/rabbit-bot/venv/lib/python3.11/site-packages/urllib3/connection.py", line 199, in _new_conn
    sock = connection.create_connection(
           ^^^^^^^^^^^^^^^^^^^^^^^^^^^^^
  File "/Users/Scoring/Desktop/rabbit-bot/venv/lib/python3.11/site-packages/urllib3/util/connection.py", line 60, in create_connection
    for res in socket.getaddrinfo(host, port, family, socket.SOCK_STREAM):
               ^^^^^^^^^^^^^^^^^^^^^^^^^^^^^^^^^^^^^^^^^^^^^^^^^^^^^^^^^^
  File "/Library/Frameworks/Python.framework/Versions/3.11/lib/python3.11/socket.py", line 962, in getaddrinfo
    for res in _socket.getaddrinfo(host, port, family, type, proto, flags):
               ^^^^^^^^^^^^^^^^^^^^^^^^^^^^^^^^^^^^^^^^^^^^^^^^^^^^^^^^^^^
socket.gaierror: [Errno 8] nodename nor servname provided, or not known

The above exception was the direct cause of the following exception:

Traceback (most recent call last):
  File "/Users/Scoring/Desktop/rabbit-bot/venv/lib/python3.11/site-packages/urllib3/connectionpool.py", line 789, in urlopen
    response = self._make_request(
               ^^^^^^^^^^^^^^^^^^^
  File "/Users/Scoring/Desktop/rabbit-bot/venv/lib/python3.11/site-packages/urllib3/connectionpool.py", line 490, in _make_request
    raise new_e
  File "/Users/Scoring/Desktop/rabbit-bot/venv/lib/python3.11/site-packages/urllib3/connectionpool.py", line 466, in _make_request
    self._validate_conn(conn)
  File "/Users/Scoring/Desktop/rabbit-bot/venv/lib/python3.11/site-packages/urllib3/connectionpool.py", line 1095, in _validate_conn
    conn.connect()
  File "/Users/Scoring/Desktop/rabbit-bot/venv/lib/python3.11/site-packages/urllib3/connection.py", line 693, in connect
    self.sock = sock = self._new_conn()
                       ^^^^^^^^^^^^^^^^
  File "/Users/Scoring/Desktop/rabbit-bot/venv/lib/python3.11/site-packages/urllib3/connection.py", line 206, in _new_conn
    raise NameResolutionError(self.host, self, e) from e
urllib3.exceptions.NameResolutionError: <urllib3.connection.HTTPSConnection object at 0x10c4d9690>: Failed to resolve 'rabbitbot-9afc1-default-rtdb.firebaseio.com' ([Errno 8] nodename nor servname provided, or not known)

The above exception was the direct cause of the following exception:

Traceback (most recent call last):
  File "/Users/Scoring/Desktop/rabbit-bot/venv/lib/python3.11/site-packages/requests/adapters.py", line 667, in send
    resp = conn.urlopen(
           ^^^^^^^^^^^^^
  File "/Users/Scoring/Desktop/rabbit-bot/venv/lib/python3.11/site-packages/urllib3/connectionpool.py", line 873, in urlopen
    return self.urlopen(
           ^^^^^^^^^^^^^
  File "/Users/Scoring/Desktop/rabbit-bot/venv/lib/python3.11/site-packages/urllib3/connectionpool.py", line 843, in urlopen
    retries = retries.increment(
              ^^^^^^^^^^^^^^^^^^
  File "/Users/Scoring/Desktop/rabbit-bot/venv/lib/python3.11/site-packages/urllib3/util/retry.py", line 519, in increment
    raise MaxRetryError(_pool, url, reason) from reason  # type: ignore[arg-type]
    ^^^^^^^^^^^^^^^^^^^^^^^^^^^^^^^^^^^^^^^^^^^^^^^^^^^
urllib3.exceptions.MaxRetryError: HTTPSConnectionPool(host='rabbitbot-9afc1-default-rtdb.firebaseio.com', port=443): Max retries exceeded with url: /orders.json (Caused by NameResolutionError("<urllib3.connection.HTTPSConnection object at 0x10c4d9690>: Failed to resolve 'rabbitbot-9afc1-default-rtdb.firebaseio.com' ([Errno 8] nodename nor servname provided, or not known)"))

During handling of the above exception, another exception occurred:

Traceback (most recent call last):
  File "/Users/Scoring/Desktop/rabbit-bot/venv/lib/python3.11/site-packages/firebase_admin/db.py", line 929, in request
    return super(_Client, self).request(method, url, **kwargs)
           ^^^^^^^^^^^^^^^^^^^^^^^^^^^^^^^^^^^^^^^^^^^^^^^^^^^
  File "/Users/Scoring/Desktop/rabbit-bot/venv/lib/python3.11/site-packages/firebase_admin/_http_client.py", line 118, in request
    resp = self._session.request(method, self.base_url + url, **kwargs)
           ^^^^^^^^^^^^^^^^^^^^^^^^^^^^^^^^^^^^^^^^^^^^^^^^^^^^^^^^^^^^
  File "/Users/Scoring/Desktop/rabbit-bot/venv/lib/python3.11/site-packages/google/auth/transport/requests.py", line 538, in request
    response = super(AuthorizedSession, self).request(
               ^^^^^^^^^^^^^^^^^^^^^^^^^^^^^^^^^^^^^^^
  File "/Users/Scoring/Desktop/rabbit-bot/venv/lib/python3.11/site-packages/requests/sessions.py", line 589, in request
    resp = self.send(prep, **send_kwargs)
           ^^^^^^^^^^^^^^^^^^^^^^^^^^^^^^
  File "/Users/Scoring/Desktop/rabbit-bot/venv/lib/python3.11/site-packages/requests/sessions.py", line 703, in send
    r = adapter.send(request, **kwargs)
        ^^^^^^^^^^^^^^^^^^^^^^^^^^^^^^^
  File "/Users/Scoring/Desktop/rabbit-bot/venv/lib/python3.11/site-packages/requests/adapters.py", line 700, in send
    raise ConnectionError(e, request=request)
requests.exceptions.ConnectionError: HTTPSConnectionPool(host='rabbitbot-9afc1-default-rtdb.firebaseio.com', port=443): Max retries exceeded with url: /orders.json (Caused by NameResolutionError("<urllib3.connection.HTTPSConnection object at 0x10c4d9690>: Failed to resolve 'rabbitbot-9afc1-default-rtdb.firebaseio.com' ([Errno 8] nodename nor servname provided, or not known)"))

During handling of the above exception, another exception occurred:

Traceback (most recent call last):
  File "/Users/Scoring/Desktop/rabbit-bot/venv/lib/python3.11/site-packages/aiogram/dispatcher/dispatcher.py", line 415, in _process_polling_updates
    for responses in itertools.chain.from_iterable(await self.process_updates(updates, fast)):
                                                   ^^^^^^^^^^^^^^^^^^^^^^^^^^^^^^^^^^^^^^^^^
  File "/Users/Scoring/Desktop/rabbit-bot/venv/lib/python3.11/site-packages/aiogram/dispatcher/dispatcher.py", line 235, in process_updates
    return await asyncio.gather(*tasks)
           ^^^^^^^^^^^^^^^^^^^^^^^^^^^^
  File "/Users/Scoring/Desktop/rabbit-bot/venv/lib/python3.11/site-packages/aiogram/dispatcher/handler.py", line 117, in notify
    response = await handler_obj.handler(*args, **partial_data)
               ^^^^^^^^^^^^^^^^^^^^^^^^^^^^^^^^^^^^^^^^^^^^^^^^
  File "/Users/Scoring/Desktop/rabbit-bot/venv/lib/python3.11/site-packages/aiogram/dispatcher/dispatcher.py", line 256, in process_update
    return await self.message_handlers.notify(update.message)
           ^^^^^^^^^^^^^^^^^^^^^^^^^^^^^^^^^^^^^^^^^^^^^^^^^^
  File "/Users/Scoring/Desktop/rabbit-bot/venv/lib/python3.11/site-packages/aiogram/dispatcher/handler.py", line 117, in notify
    response = await handler_obj.handler(*args, **partial_data)
               ^^^^^^^^^^^^^^^^^^^^^^^^^^^^^^^^^^^^^^^^^^^^^^^^
  File "/Users/Scoring/Desktop/rabbit-bot/command.py", line 245, in get_user_orders
    orders_data = order_ref.get() or {}
                  ^^^^^^^^^^^^^^^
  File "/Users/Scoring/Desktop/rabbit-bot/venv/lib/python3.11/site-packages/firebase_admin/db.py", line 221, in get
    return self._client.body('get', self._add_suffix(), params=params)
           ^^^^^^^^^^^^^^^^^^^^^^^^^^^^^^^^^^^^^^^^^^^^^^^^^^^^^^^^^^^
  File "/Users/Scoring/Desktop/rabbit-bot/venv/lib/python3.11/site-packages/firebase_admin/_http_client.py", line 131, in body
    resp = self.request(method, url, **kwargs)
           ^^^^^^^^^^^^^^^^^^^^^^^^^^^^^^^^^^^
  File "/Users/Scoring/Desktop/rabbit-bot/venv/lib/python3.11/site-packages/firebase_admin/db.py", line 931, in request
    raise _Client.handle_rtdb_error(error)
firebase_admin.exceptions.UnavailableError: Failed to establish a connection: HTTPSConnectionPool(host='rabbitbot-9afc1-default-rtdb.firebaseio.com', port=443): Max retries exceeded with url: /orders.json (Caused by NameResolutionError("<urllib3.connection.HTTPSConnection object at 0x10c4d9690>: Failed to resolve 'rabbitbot-9afc1-default-rtdb.firebaseio.com' ([Errno 8] nodename nor servname provided, or not known)"))
2024-11-04 21:31:52,965 - WARNING - Retrying (Retry(total=9, connect=0, read=1, redirect=None, status=4)) after connection broken by 'NameResolutionError("<urllib3.connection.HTTPSConnection object at 0x10c4d4110>: Failed to resolve 'rabbitbot-9afc1-default-rtdb.firebaseio.com' ([Errno 8] nodename nor servname provided, or not known)")': /products.json
2024-11-04 21:31:52,973 - ERROR - Task exception was never retrieved
future: <Task finished name='Task-36' coro=<Dispatcher._process_polling_updates() done, defined at /Users/Scoring/Desktop/rabbit-bot/venv/lib/python3.11/site-packages/aiogram/dispatcher/dispatcher.py:407> exception=UnavailableError('Failed to establish a connection: HTTPSConnectionPool(host=\'rabbitbot-9afc1-default-rtdb.firebaseio.com\', port=443): Max retries exceeded with url: /products.json (Caused by NameResolutionError("<urllib3.connection.HTTPSConnection object at 0x10c4d4c10>: Failed to resolve \'rabbitbot-9afc1-default-rtdb.firebaseio.com\' ([Errno 8] nodename nor servname provided, or not known)"))')>
Traceback (most recent call last):
  File "/Users/Scoring/Desktop/rabbit-bot/venv/lib/python3.11/site-packages/urllib3/connection.py", line 199, in _new_conn
    sock = connection.create_connection(
           ^^^^^^^^^^^^^^^^^^^^^^^^^^^^^
  File "/Users/Scoring/Desktop/rabbit-bot/venv/lib/python3.11/site-packages/urllib3/util/connection.py", line 60, in create_connection
    for res in socket.getaddrinfo(host, port, family, socket.SOCK_STREAM):
               ^^^^^^^^^^^^^^^^^^^^^^^^^^^^^^^^^^^^^^^^^^^^^^^^^^^^^^^^^^
  File "/Library/Frameworks/Python.framework/Versions/3.11/lib/python3.11/socket.py", line 962, in getaddrinfo
    for res in _socket.getaddrinfo(host, port, family, type, proto, flags):
               ^^^^^^^^^^^^^^^^^^^^^^^^^^^^^^^^^^^^^^^^^^^^^^^^^^^^^^^^^^^
socket.gaierror: [Errno 8] nodename nor servname provided, or not known

The above exception was the direct cause of the following exception:

Traceback (most recent call last):
  File "/Users/Scoring/Desktop/rabbit-bot/venv/lib/python3.11/site-packages/urllib3/connectionpool.py", line 789, in urlopen
    response = self._make_request(
               ^^^^^^^^^^^^^^^^^^^
  File "/Users/Scoring/Desktop/rabbit-bot/venv/lib/python3.11/site-packages/urllib3/connectionpool.py", line 490, in _make_request
    raise new_e
  File "/Users/Scoring/Desktop/rabbit-bot/venv/lib/python3.11/site-packages/urllib3/connectionpool.py", line 466, in _make_request
    self._validate_conn(conn)
  File "/Users/Scoring/Desktop/rabbit-bot/venv/lib/python3.11/site-packages/urllib3/connectionpool.py", line 1095, in _validate_conn
    conn.connect()
  File "/Users/Scoring/Desktop/rabbit-bot/venv/lib/python3.11/site-packages/urllib3/connection.py", line 693, in connect
    self.sock = sock = self._new_conn()
                       ^^^^^^^^^^^^^^^^
  File "/Users/Scoring/Desktop/rabbit-bot/venv/lib/python3.11/site-packages/urllib3/connection.py", line 206, in _new_conn
    raise NameResolutionError(self.host, self, e) from e
urllib3.exceptions.NameResolutionError: <urllib3.connection.HTTPSConnection object at 0x10c4d4c10>: Failed to resolve 'rabbitbot-9afc1-default-rtdb.firebaseio.com' ([Errno 8] nodename nor servname provided, or not known)

The above exception was the direct cause of the following exception:

Traceback (most recent call last):
  File "/Users/Scoring/Desktop/rabbit-bot/venv/lib/python3.11/site-packages/requests/adapters.py", line 667, in send
    resp = conn.urlopen(
           ^^^^^^^^^^^^^
  File "/Users/Scoring/Desktop/rabbit-bot/venv/lib/python3.11/site-packages/urllib3/connectionpool.py", line 873, in urlopen
    return self.urlopen(
           ^^^^^^^^^^^^^
  File "/Users/Scoring/Desktop/rabbit-bot/venv/lib/python3.11/site-packages/urllib3/connectionpool.py", line 843, in urlopen
    retries = retries.increment(
              ^^^^^^^^^^^^^^^^^^
  File "/Users/Scoring/Desktop/rabbit-bot/venv/lib/python3.11/site-packages/urllib3/util/retry.py", line 519, in increment
    raise MaxRetryError(_pool, url, reason) from reason  # type: ignore[arg-type]
    ^^^^^^^^^^^^^^^^^^^^^^^^^^^^^^^^^^^^^^^^^^^^^^^^^^^
urllib3.exceptions.MaxRetryError: HTTPSConnectionPool(host='rabbitbot-9afc1-default-rtdb.firebaseio.com', port=443): Max retries exceeded with url: /products.json (Caused by NameResolutionError("<urllib3.connection.HTTPSConnection object at 0x10c4d4c10>: Failed to resolve 'rabbitbot-9afc1-default-rtdb.firebaseio.com' ([Errno 8] nodename nor servname provided, or not known)"))

During handling of the above exception, another exception occurred:

Traceback (most recent call last):
  File "/Users/Scoring/Desktop/rabbit-bot/venv/lib/python3.11/site-packages/firebase_admin/db.py", line 929, in request
    return super(_Client, self).request(method, url, **kwargs)
           ^^^^^^^^^^^^^^^^^^^^^^^^^^^^^^^^^^^^^^^^^^^^^^^^^^^
  File "/Users/Scoring/Desktop/rabbit-bot/venv/lib/python3.11/site-packages/firebase_admin/_http_client.py", line 118, in request
    resp = self._session.request(method, self.base_url + url, **kwargs)
           ^^^^^^^^^^^^^^^^^^^^^^^^^^^^^^^^^^^^^^^^^^^^^^^^^^^^^^^^^^^^
  File "/Users/Scoring/Desktop/rabbit-bot/venv/lib/python3.11/site-packages/google/auth/transport/requests.py", line 538, in request
    response = super(AuthorizedSession, self).request(
               ^^^^^^^^^^^^^^^^^^^^^^^^^^^^^^^^^^^^^^^
  File "/Users/Scoring/Desktop/rabbit-bot/venv/lib/python3.11/site-packages/requests/sessions.py", line 589, in request
    resp = self.send(prep, **send_kwargs)
           ^^^^^^^^^^^^^^^^^^^^^^^^^^^^^^
  File "/Users/Scoring/Desktop/rabbit-bot/venv/lib/python3.11/site-packages/requests/sessions.py", line 703, in send
    r = adapter.send(request, **kwargs)
        ^^^^^^^^^^^^^^^^^^^^^^^^^^^^^^^
  File "/Users/Scoring/Desktop/rabbit-bot/venv/lib/python3.11/site-packages/requests/adapters.py", line 700, in send
    raise ConnectionError(e, request=request)
requests.exceptions.ConnectionError: HTTPSConnectionPool(host='rabbitbot-9afc1-default-rtdb.firebaseio.com', port=443): Max retries exceeded with url: /products.json (Caused by NameResolutionError("<urllib3.connection.HTTPSConnection object at 0x10c4d4c10>: Failed to resolve 'rabbitbot-9afc1-default-rtdb.firebaseio.com' ([Errno 8] nodename nor servname provided, or not known)"))

During handling of the above exception, another exception occurred:

Traceback (most recent call last):
  File "/Users/Scoring/Desktop/rabbit-bot/venv/lib/python3.11/site-packages/aiogram/dispatcher/dispatcher.py", line 415, in _process_polling_updates
    for responses in itertools.chain.from_iterable(await self.process_updates(updates, fast)):
                                                   ^^^^^^^^^^^^^^^^^^^^^^^^^^^^^^^^^^^^^^^^^
  File "/Users/Scoring/Desktop/rabbit-bot/venv/lib/python3.11/site-packages/aiogram/dispatcher/dispatcher.py", line 235, in process_updates
    return await asyncio.gather(*tasks)
           ^^^^^^^^^^^^^^^^^^^^^^^^^^^^
  File "/Users/Scoring/Desktop/rabbit-bot/venv/lib/python3.11/site-packages/aiogram/dispatcher/handler.py", line 117, in notify
    response = await handler_obj.handler(*args, **partial_data)
               ^^^^^^^^^^^^^^^^^^^^^^^^^^^^^^^^^^^^^^^^^^^^^^^^
  File "/Users/Scoring/Desktop/rabbit-bot/venv/lib/python3.11/site-packages/aiogram/dispatcher/dispatcher.py", line 256, in process_update
    return await self.message_handlers.notify(update.message)
           ^^^^^^^^^^^^^^^^^^^^^^^^^^^^^^^^^^^^^^^^^^^^^^^^^^
  File "/Users/Scoring/Desktop/rabbit-bot/venv/lib/python3.11/site-packages/aiogram/dispatcher/handler.py", line 117, in notify
    response = await handler_obj.handler(*args, **partial_data)
               ^^^^^^^^^^^^^^^^^^^^^^^^^^^^^^^^^^^^^^^^^^^^^^^^
  File "/Users/Scoring/Desktop/rabbit-bot/command.py", line 126, in display_categories
    products_data = products_ref.get()
                    ^^^^^^^^^^^^^^^^^^
  File "/Users/Scoring/Desktop/rabbit-bot/venv/lib/python3.11/site-packages/firebase_admin/db.py", line 221, in get
    return self._client.body('get', self._add_suffix(), params=params)
           ^^^^^^^^^^^^^^^^^^^^^^^^^^^^^^^^^^^^^^^^^^^^^^^^^^^^^^^^^^^
  File "/Users/Scoring/Desktop/rabbit-bot/venv/lib/python3.11/site-packages/firebase_admin/_http_client.py", line 131, in body
    resp = self.request(method, url, **kwargs)
           ^^^^^^^^^^^^^^^^^^^^^^^^^^^^^^^^^^^
  File "/Users/Scoring/Desktop/rabbit-bot/venv/lib/python3.11/site-packages/firebase_admin/db.py", line 931, in request
    raise _Client.handle_rtdb_error(error)
firebase_admin.exceptions.UnavailableError: Failed to establish a connection: HTTPSConnectionPool(host='rabbitbot-9afc1-default-rtdb.firebaseio.com', port=443): Max retries exceeded with url: /products.json (Caused by NameResolutionError("<urllib3.connection.HTTPSConnection object at 0x10c4d4c10>: Failed to resolve 'rabbitbot-9afc1-default-rtdb.firebaseio.com' ([Errno 8] nodename nor servname provided, or not known)"))
2024-11-04 21:37:29,658 - INFO - Stop polling...
2024-11-04 21:37:29,671 - WARNING - Goodbye!
2024-11-04 21:43:33,129 - INFO - Bot: RabbitHole Bot [@rabbit4ogs_bot]
2024-11-04 21:43:35,684 - WARNING - Updates were skipped successfully.
2024-11-04 21:43:35,685 - INFO - Start polling.
2024-11-04 21:44:49,766 - INFO - Sent message ID: 27 (Type: <class 'int'>)
2024-11-04 21:44:51,249 - INFO - Sent message ID: 29 (Type: <class 'int'>)
2024-11-04 21:46:58,108 - INFO - Stop polling...
2024-11-04 21:46:58,122 - WARNING - Goodbye!
2024-11-04 21:47:52,332 - INFO - Bot: RabbitHole Bot [@rabbit4ogs_bot]
2024-11-04 21:47:52,780 - WARNING - Updates were skipped successfully.
2024-11-04 21:47:52,780 - INFO - Start polling.
2024-11-04 21:50:59,722 - ERROR - Task exception was never retrieved
future: <Task finished name='Task-22' coro=<Dispatcher._process_polling_updates() done, defined at /Users/Scoring/Desktop/rabbit-bot/venv/lib/python3.11/site-packages/aiogram/dispatcher/dispatcher.py:407> exception=AttributeError("'str' object has no attribute 'get'")>
Traceback (most recent call last):
  File "/Users/Scoring/Desktop/rabbit-bot/venv/lib/python3.11/site-packages/aiogram/dispatcher/dispatcher.py", line 415, in _process_polling_updates
    for responses in itertools.chain.from_iterable(await self.process_updates(updates, fast)):
                                                   ^^^^^^^^^^^^^^^^^^^^^^^^^^^^^^^^^^^^^^^^^
  File "/Users/Scoring/Desktop/rabbit-bot/venv/lib/python3.11/site-packages/aiogram/dispatcher/dispatcher.py", line 235, in process_updates
    return await asyncio.gather(*tasks)
           ^^^^^^^^^^^^^^^^^^^^^^^^^^^^
  File "/Users/Scoring/Desktop/rabbit-bot/venv/lib/python3.11/site-packages/aiogram/dispatcher/handler.py", line 117, in notify
    response = await handler_obj.handler(*args, **partial_data)
               ^^^^^^^^^^^^^^^^^^^^^^^^^^^^^^^^^^^^^^^^^^^^^^^^
  File "/Users/Scoring/Desktop/rabbit-bot/venv/lib/python3.11/site-packages/aiogram/dispatcher/dispatcher.py", line 256, in process_update
    return await self.message_handlers.notify(update.message)
           ^^^^^^^^^^^^^^^^^^^^^^^^^^^^^^^^^^^^^^^^^^^^^^^^^^
  File "/Users/Scoring/Desktop/rabbit-bot/venv/lib/python3.11/site-packages/aiogram/dispatcher/handler.py", line 117, in notify
    response = await handler_obj.handler(*args, **partial_data)
               ^^^^^^^^^^^^^^^^^^^^^^^^^^^^^^^^^^^^^^^^^^^^^^^^
  File "/Users/Scoring/Desktop/rabbit-bot/command.py", line 644, in handle_delete_message
    await delete_message(message_id_to_delete, message, admins)
  File "/Users/Scoring/Desktop/rabbit-bot/command.py", line 660, in delete_message
    numeric_id = sent_message_data.get('numeric_id')  # Get the numeric ID
                 ^^^^^^^^^^^^^^^^^^^^^
AttributeError: 'str' object has no attribute 'get'
2024-11-04 21:53:33,855 - INFO - Stop polling...
2024-11-04 21:53:33,867 - WARNING - Goodbye!
2024-11-04 21:53:50,050 - INFO - Bot: RabbitHole Bot [@rabbit4ogs_bot]
2024-11-04 21:53:50,704 - WARNING - Updates were skipped successfully.
2024-11-04 21:53:50,704 - INFO - Start polling.
2024-11-04 21:54:01,782 - INFO - Successfully deleted message ID: 27 from channel ID: -1002487692776.
2024-11-04 21:54:02,524 - INFO - Successfully deleted message ID: 27 from channel ID: -1002392924508.
2024-11-04 21:54:02,934 - ERROR - Failed to delete message ID: 29 from channel ID: -1002487692776. Error: Message to delete not found
2024-11-04 21:54:03,213 - INFO - Successfully deleted message ID: 29 from channel ID: -1002392924508.
2024-11-04 21:54:03,884 - INFO - Deleted message ID: -OAsv3fnY5xk4hopn_bN from the database.
2024-11-04 21:55:22,651 - INFO - Sent message ID: 28 (Type: <class 'int'>)
2024-11-04 21:55:23,558 - INFO - Sent message ID: 30 (Type: <class 'int'>)
2024-11-04 21:56:00,065 - INFO - Stop polling...
2024-11-04 21:56:00,066 - WARNING - Goodbye!
2024-11-04 21:58:52,487 - INFO - Bot: RabbitHole Bot [@rabbit4ogs_bot]
2024-11-04 21:58:53,032 - WARNING - Updates were skipped successfully.
2024-11-04 21:58:53,033 - INFO - Start polling.
2024-11-04 21:59:57,666 - INFO - Successfully deleted message ID: 28 from channel ID: -1002487692776.
2024-11-04 21:59:58,008 - INFO - Successfully deleted message ID: 28 from channel ID: -1002392924508.
2024-11-04 21:59:58,409 - ERROR - Failed to delete message ID: 30 from channel ID: -1002487692776. Error: Message to delete not found
2024-11-04 21:59:58,773 - INFO - Successfully deleted message ID: 30 from channel ID: -1002392924508.
2024-11-04 21:59:59,490 - INFO - Deleted message ID: -OAsxUZ5KDJJ4LW5CPZF from the database.
2024-11-04 22:07:25,517 - INFO - Stop polling...
2024-11-04 22:07:25,569 - WARNING - Goodbye!
2024-11-04 22:09:12,532 - INFO - Bot: RabbitHole Bot [@rabbit4ogs_bot]
2024-11-04 22:09:12,882 - WARNING - Updates were skipped successfully.
2024-11-04 22:09:12,883 - WARNING - Goodbye!
2024-11-04 22:09:38,499 - INFO - Bot: RabbitHole Bot [@rabbit4ogs_bot]
2024-11-04 22:09:38,811 - WARNING - Updates were skipped successfully.
2024-11-04 22:09:42,752 - INFO - Start polling.
2024-11-04 22:10:06,917 - INFO - Sent message ID: 29 (Type: <class 'int'>)
2024-11-04 22:10:07,830 - INFO - Sent message ID: 31 (Type: <class 'int'>)
2024-11-04 22:11:44,054 - ERROR - Failed to delete message ID: 29 from channel ID: -1002487692776. Error: 'NoneType' object has no attribute 'bot'
2024-11-04 22:11:44,063 - ERROR - Failed to delete message ID: 29 from channel ID: -1002392924508. Error: 'NoneType' object has no attribute 'bot'
2024-11-04 22:11:44,063 - ERROR - Failed to delete message ID: 31 from channel ID: -1002487692776. Error: 'NoneType' object has no attribute 'bot'
2024-11-04 22:11:44,063 - ERROR - Failed to delete message ID: 31 from channel ID: -1002392924508. Error: 'NoneType' object has no attribute 'bot'
2024-11-04 22:11:44,540 - INFO - Deleted message ID: -OAt-rPW4a7Oo_tTC7w4 from the database.
2024-11-04 22:11:44,541 - ERROR - Task exception was never retrieved
future: <Task finished name='Task-6' coro=<delete_oldest_message() done, defined at /Users/Scoring/Desktop/rabbit-bot/command.py:611> exception=AttributeError("'NoneType' object has no attribute 'reply'")>
Traceback (most recent call last):
  File "/Users/Scoring/Desktop/rabbit-bot/command.py", line 635, in delete_oldest_message
    await delete_message(oldest_message_id, None, None)
  File "/Users/Scoring/Desktop/rabbit-bot/command.py", line 607, in delete_message
    await message.reply("Message has been deleted from the channel and database.")
          ^^^^^^^^^^^^^
AttributeError: 'NoneType' object has no attribute 'reply'
2024-11-04 22:15:29,585 - INFO - Sent message ID: 30 (Type: <class 'int'>)
2024-11-04 22:15:30,291 - INFO - Sent message ID: 32 (Type: <class 'int'>)
2024-11-04 22:15:33,409 - INFO - Sent message ID: 31 (Type: <class 'int'>)
2024-11-04 22:15:35,316 - INFO - Sent message ID: 33 (Type: <class 'int'>)
2024-11-04 22:15:40,677 - INFO - Sent message ID: 32 (Type: <class 'int'>)
2024-11-04 22:15:42,516 - INFO - Sent message ID: 34 (Type: <class 'int'>)
2024-11-04 22:16:55,463 - INFO - Successfully deleted message ID: 32 from channel ID: -1002487692776.
2024-11-04 22:16:56,108 - INFO - Successfully deleted message ID: 32 from channel ID: -1002392924508.
2024-11-04 22:16:56,423 - ERROR - Failed to delete message ID: 34 from channel ID: -1002487692776. Error: Message to delete not found
2024-11-04 22:16:56,715 - INFO - Successfully deleted message ID: 34 from channel ID: -1002392924508.
2024-11-04 22:16:57,167 - INFO - Deleted message ID: -OAt17g9_41WpTVcBRRg from the database.
2024-11-04 22:19:18,733 - INFO - Successfully deleted message ID: 31 from channel ID: -1002487692776.
2024-11-04 22:19:19,002 - INFO - Successfully deleted message ID: 31 from channel ID: -1002392924508.
2024-11-04 22:19:19,332 - ERROR - Failed to delete message ID: 33 from channel ID: -1002487692776. Error: Message to delete not found
2024-11-04 22:19:19,632 - INFO - Successfully deleted message ID: 33 from channel ID: -1002392924508.
2024-11-04 22:19:19,967 - INFO - Deleted message ID: -OAt165aVHOHx1F-2kOS from the database.
2024-11-04 22:21:12,063 - INFO - Stop polling...
2024-11-04 22:21:12,073 - WARNING - Goodbye!
2024-11-04 22:21:16,608 - INFO - Bot: RabbitHole Bot [@rabbit4ogs_bot]
2024-11-04 22:21:17,177 - WARNING - Updates were skipped successfully.
2024-11-04 22:21:21,675 - ERROR - Failed to delete message ID: 30 from channel ID: -1002487692776. Error: 'NoneType' object has no attribute 'bot'
2024-11-04 22:21:21,676 - ERROR - Failed to delete message ID: 30 from channel ID: -1002392924508. Error: 'NoneType' object has no attribute 'bot'
2024-11-04 22:21:21,676 - ERROR - Failed to delete message ID: 32 from channel ID: -1002487692776. Error: 'NoneType' object has no attribute 'bot'
2024-11-04 22:21:21,676 - ERROR - Failed to delete message ID: 32 from channel ID: -1002392924508. Error: 'NoneType' object has no attribute 'bot'
2024-11-04 22:21:21,959 - INFO - Deleted message ID: -OAt15BFCL211WCwad1s from the database.
2024-11-04 22:21:21,959 - ERROR - Task exception was never retrieved
future: <Task finished name='Task-6' coro=<delete_oldest_message() done, defined at /Users/Scoring/Desktop/rabbit-bot/command.py:611> exception=AttributeError("'NoneType' object has no attribute 'reply'")>
Traceback (most recent call last):
  File "/Users/Scoring/Desktop/rabbit-bot/command.py", line 635, in delete_oldest_message
    await delete_message(oldest_message_id, None, None)
  File "/Users/Scoring/Desktop/rabbit-bot/command.py", line 607, in delete_message
    await message.reply("Message has been deleted from the channel and database.")
          ^^^^^^^^^^^^^
AttributeError: 'NoneType' object has no attribute 'reply'
2024-11-04 22:21:21,970 - INFO - Start polling.
2024-11-04 22:26:56,024 - INFO - Stop polling...
2024-11-04 22:26:56,038 - WARNING - Goodbye!
2024-11-04 22:27:16,524 - INFO - Bot: RabbitHole Bot [@rabbit4ogs_bot]
2024-11-04 22:27:16,857 - WARNING - Updates were skipped successfully.
2024-11-04 22:27:19,498 - INFO - No messages to delete.
2024-11-04 22:27:19,499 - INFO - Start polling.
2024-11-04 22:29:20,216 - INFO - No messages to delete.
2024-11-04 22:29:37,773 - INFO - Stop polling...
2024-11-04 22:29:37,774 - WARNING - Goodbye!
2024-11-04 22:30:40,580 - INFO - Bot: RabbitHole Bot [@rabbit4ogs_bot]
2024-11-04 22:30:40,928 - WARNING - Updates were skipped successfully.
2024-11-04 22:30:42,389 - INFO - No messages to delete.
2024-11-04 22:30:42,390 - INFO - Start polling.
2024-11-04 22:31:22,281 - INFO - Sent message ID: 33 (Type: <class 'int'>)
2024-11-04 22:31:23,097 - INFO - Sent message ID: 35 (Type: <class 'int'>)
2024-11-04 22:31:55,772 - INFO - Sent message ID: 34 (Type: <class 'int'>)
2024-11-04 22:31:56,542 - INFO - Sent message ID: 36 (Type: <class 'int'>)
2024-11-04 22:32:02,575 - INFO - Sent message ID: 35 (Type: <class 'int'>)
2024-11-04 22:32:03,852 - INFO - Sent message ID: 37 (Type: <class 'int'>)
2024-11-04 22:32:42,949 - INFO - Attempting to delete the oldest message ID: -OAt4icuCMe_KTU9EIMw.
2024-11-04 22:32:43,375 - ERROR - Failed to delete message ID: 33 from channel ID: -1002487692776. Error: 'NoneType' object has no attribute 'bot'
2024-11-04 22:32:43,376 - ERROR - Failed to delete message ID: 33 from channel ID: -1002392924508. Error: 'NoneType' object has no attribute 'bot'
2024-11-04 22:32:43,376 - ERROR - Failed to delete message ID: 33 from channel ID: -1002340916811. Error: 'NoneType' object has no attribute 'bot'
2024-11-04 22:32:43,376 - ERROR - Failed to delete message ID: 35 from channel ID: -1002487692776. Error: 'NoneType' object has no attribute 'bot'
2024-11-04 22:32:43,376 - ERROR - Failed to delete message ID: 35 from channel ID: -1002392924508. Error: 'NoneType' object has no attribute 'bot'
2024-11-04 22:32:43,376 - ERROR - Failed to delete message ID: 35 from channel ID: -1002340916811. Error: 'NoneType' object has no attribute 'bot'
2024-11-04 22:32:43,744 - INFO - Deleted message ID: -OAt4icuCMe_KTU9EIMw from the database.
2024-11-04 22:34:50,763 - INFO - Attempting to delete the oldest message ID: -OAt4qwcedvzPx7XGoh-.
2024-11-04 22:34:51,140 - ERROR - Failed to delete message ID: 34 from channel ID: -1002487692776. Error: 'NoneType' object has no attribute 'bot'
2024-11-04 22:34:51,153 - ERROR - Failed to delete message ID: 34 from channel ID: -1002392924508. Error: 'NoneType' object has no attribute 'bot'
2024-11-04 22:34:51,154 - ERROR - Failed to delete message ID: 34 from channel ID: -1002340916811. Error: 'NoneType' object has no attribute 'bot'
2024-11-04 22:34:51,154 - ERROR - Failed to delete message ID: 36 from channel ID: -1002487692776. Error: 'NoneType' object has no attribute 'bot'
2024-11-04 22:34:51,155 - ERROR - Failed to delete message ID: 36 from channel ID: -1002392924508. Error: 'NoneType' object has no attribute 'bot'
2024-11-04 22:34:51,155 - ERROR - Failed to delete message ID: 36 from channel ID: -1002340916811. Error: 'NoneType' object has no attribute 'bot'
2024-11-04 22:34:51,500 - INFO - Deleted message ID: -OAt4qwcedvzPx7XGoh- from the database.
2024-11-04 22:36:53,393 - INFO - Attempting to delete the oldest message ID: -OAt4sVedtSTeAvSv8en.
2024-11-04 22:36:53,785 - ERROR - Failed to delete message ID: 35 from channel ID: -1002487692776. Error: 'NoneType' object has no attribute 'bot'
2024-11-04 22:36:53,786 - ERROR - Failed to delete message ID: 35 from channel ID: -1002392924508. Error: 'NoneType' object has no attribute 'bot'
2024-11-04 22:36:53,786 - ERROR - Failed to delete message ID: 35 from channel ID: -1002340916811. Error: 'NoneType' object has no attribute 'bot'
2024-11-04 22:36:53,786 - ERROR - Failed to delete message ID: 37 from channel ID: -1002487692776. Error: 'NoneType' object has no attribute 'bot'
2024-11-04 22:36:53,786 - ERROR - Failed to delete message ID: 37 from channel ID: -1002392924508. Error: 'NoneType' object has no attribute 'bot'
2024-11-04 22:36:53,786 - ERROR - Failed to delete message ID: 37 from channel ID: -1002340916811. Error: 'NoneType' object has no attribute 'bot'
2024-11-04 22:36:54,659 - INFO - Deleted message ID: -OAt4sVedtSTeAvSv8en from the database.
2024-11-04 22:38:57,117 - INFO - No messages to delete.
2024-11-04 22:40:38,117 - INFO - Stop polling...
2024-11-04 22:40:38,129 - WARNING - Goodbye!
2024-11-04 22:41:02,362 - INFO - Bot: RabbitHole Bot [@rabbit4ogs_bot]
2024-11-04 22:41:02,952 - WARNING - Updates were skipped successfully.
2024-11-04 22:41:09,221 - INFO - No messages to delete.
2024-11-04 22:41:09,222 - INFO - Start polling.
2024-11-04 22:42:43,567 - INFO - Stop polling...
2024-11-04 22:42:43,577 - WARNING - Goodbye!
2024-11-04 22:43:28,229 - INFO - Bot: RabbitHole Bot [@rabbit4ogs_bot]
2024-11-04 22:43:28,568 - WARNING - Updates were skipped successfully.
2024-11-04 22:43:31,058 - INFO - No messages to delete.
2024-11-04 22:43:31,059 - INFO - Start polling.
2024-11-04 22:43:41,835 - INFO - Sent message ID: 2 (Type: <class 'int'>)
2024-11-04 22:43:53,279 - INFO - Sent message ID: 3 (Type: <class 'int'>)
2024-11-04 22:43:58,992 - INFO - Sent message ID: 4 (Type: <class 'int'>)
2024-11-04 22:45:31,768 - INFO - Attempting to delete the oldest message ID: -OAt7YLpc8EY65ZXvrpK.
2024-11-04 22:45:33,918 - INFO - Successfully deleted message ID: 2 from channel ID: -1002340916811.
2024-11-04 22:45:34,183 - INFO - Deleted message ID: -OAt7YLpc8EY65ZXvrpK from the database.
2024-11-04 22:45:34,183 - ERROR - Task exception was never retrieved
future: <Task finished name='Task-6' coro=<delete_oldest_message() done, defined at /Users/Scoring/Desktop/rabbit-bot/command.py:617> exception=AttributeError("'DummyMessage' object has no attribute 'reply'")>
Traceback (most recent call last):
  File "/Users/Scoring/Desktop/rabbit-bot/command.py", line 640, in delete_oldest_message
    await delete_message(oldest_message_id, dummy_message, None)
  File "/Users/Scoring/Desktop/rabbit-bot/command.py", line 609, in delete_message
    await message.reply("Message has been deleted from the channel and database.")
          ^^^^^^^^^^^^^
AttributeError: 'DummyMessage' object has no attribute 'reply'
2024-11-04 22:48:28,565 - INFO - Stop polling...
2024-11-04 22:48:28,577 - WARNING - Goodbye!
2024-11-04 22:48:33,519 - INFO - Bot: RabbitHole Bot [@rabbit4ogs_bot]
2024-11-04 22:48:33,926 - WARNING - Updates were skipped successfully.
2024-11-04 22:48:44,196 - INFO - Attempting to delete the oldest message ID: -OAt7a8CD5_qU8zcxkXu.
2024-11-04 22:48:44,568 - INFO - Start polling.
2024-11-04 22:48:45,335 - INFO - Successfully deleted message ID: 3 from channel ID: -1002340916811.
2024-11-04 22:48:45,953 - INFO - Deleted message ID: -OAt7a8CD5_qU8zcxkXu from the database.
2024-11-04 22:48:45,954 - INFO - Dummy reply: Message has been deleted from the channel and database.
2024-11-04 22:50:48,079 - INFO - Attempting to delete the oldest message ID: -OAt7bOerMsYdnlg5Iq5.
2024-11-04 22:50:50,417 - INFO - Successfully deleted message ID: 4 from channel ID: -1002340916811.
2024-11-04 22:50:51,633 - INFO - Deleted message ID: -OAt7bOerMsYdnlg5Iq5 from the database.
2024-11-04 22:50:51,634 - INFO - Dummy reply: Message has been deleted from the channel and database.
2024-11-04 22:52:52,411 - INFO - No messages to delete.
2024-11-04 22:54:54,604 - INFO - No messages to delete.
2024-11-04 22:56:56,979 - INFO - No messages to delete.
2024-11-04 22:58:58,733 - INFO - No messages to delete.
2024-11-04 22:59:05,318 - INFO - Stop polling...
2024-11-04 22:59:05,319 - WARNING - Goodbye!
